Workbook

Sheet Instructions
B1: Tip Pool Calculator - How To Use
B3: 1. Paste your Time Card Report
B4: Open the 'Time Card Data' tab. Delete any old data below row 1, then paste your new report starting at cell A2, keeping the exact same columns as your system export (Name, Role, Pay rate, Date, Time in, Time out, Regular Hours, Overtime, Double Overtime, Weekly Overtime, Paid Breaks hours, UnPaid Breaks hours, Total Hours, Net Sale, Tips, Gratuity). Do not paste over columns Q onward - those are calculated automatically.
B5: 2. Set up your Settings tab
B6: Go to the 'Settings' tab. Set the Pay Period Start Date to the first date in your report (the year is taken from this date). Choose the Tip Distribution Method: Percentage, Points, or Equally. Then fill in the Role table: for every Role that appears in your time card, say whether it Contributes to the pool, by what method (% of Sales or % of Tips) and what %, whether it Receives from the pool, and its Distribution % (Percentage method) or Points per Hour (Points method).
B7: 3. Everything else calculates automatically
B8: The 'Time Card Data' tab calculates, for every shift: the contribution to the pool, the tips the employee keeps directly, and the pool amount they receive back - based only on who actually worked that specific date. A different pool is built and split for every date. 'Pool by Date' shows the pool total for each day. 'Employee Totals' rolls everything up per employee for the whole period.
B9: How the 3 distribution methods work
B10: Percentage - the day's pool is split across roles using each role's Distribution %. Within a role, the role's dollar bucket is split among that role's employees in proportion to hours worked that day.
B11: Points - each recipient employee's hours worked that day are multiplied by their role's Points per Hour. The pool is divided by the total point-hours worked that day to get a $-per-point-hour rate, then paid out by each person's point-hours.
B12: Equally - the pool is divided by the total hours worked that day (across all recipient roles), then paid out per hour worked - regardless of role.
B13: How contribution works
... B19: - The Time Card Data tab supports up to 600 rows, Employee Totals up to 60 unique employees, and Pool by Date up to the 'Number of Days to Calculate' set on the Settings tab. Extend these by copying the last row's formulas down further if you need more.

Sheet Settings
A1: Settings
A3: Pay Period Start Date | B3: 46272 | C3: <- first date in your time card report (year is used for all dates)
A4: Number of Days to Calculate | B4: 31 | C4: <- how many days the 'Pool by Date' tab should list
A6: Tip Distribution Method | B6: Equally | C6: <- choose: Percentage, Points, or Equally
A9: Role Rules
A10: Every Role that appears in your time card should have a row below. Edit freely.
A11: Role | B11: Contributes to Pool? | C11: Contribution Method | D11: Contribution % | E11: Receives from Pool? | F11: Distribution % (Percentage method) | G11: Points per Hour (Points method)
A12: Barista | B12: N | C12: % of Tips | D12: 0 | E12: Y | F12: 1 | G12: 1
A13: Owner | B13: N | C13: % of Tips | D13: 0 | E13: N | F13: 0 | G13: 1
A14: Server | B14: N | C14: % of Tips | D14: 0 | E14: N | F14: 0 | G14: 1
A15: Bartender | B15: N | C15: % of Tips | D15: 0 | E15: N | F15: 0 | G15: 1
A16: Cashier | B16: N | C16: % of Tips | D16: 0 | E16: N | F16: 0 | G16: 1
A17: Summary | B17: Y | C17: % of Tips | D17: 1 | E17: N | G17: 1
A18: Kiosk | B18: Y | C18: % of Tips | D18: 1 | E18: N | G18: 1
A43: Check: Distribution % of recipient roles sums to | D43: =SUMIF(E12:E41,"Y",F12:F41) -> 1 | E43: (should be 100% when method = Percentage)

Sheet Time Card Data
A1: Name | B1: Role | C1: Pay rate | D1: Date | E1: Time in | G1: Time out | H1: Regular Hours | I1: Overtime | J1: Double Overtime | K1: Weekly Overtime | L1: Paid Breaks hours | M1: UnPaid Breaks hours | N1: Total Hours (excluding unpaid breaks) | O1: Net Sale | P1: Tips | Q1: Gratuity | R1: Employee | S1: Is Data Row? | T1: Date (parsed) | U1: Contributes? | V1: Contribution Method | W1: Contribution % | X1: Contribution Amount | Y1: Kept Tips | Z1: Receives? | AA1: Distribution % | AB1: Points/Hour | AC1: Day Pool Total | AD1: Role-Hours That Day | AE1: Recipient Hours That Day | AF1: Recipient Point-Hours That Day | AG1: Pool Share | AH1: Total Payout | AI1: First Occurrence? | AJ1: Unique Employee #
A2: Scott Okano | B2: Barista | C2: 19.75 | D2: 46272 | E2: 0.39861111 | G2: 0.70625 | H2: 6.87 | I2: 0 | J2: 0 | L2: 0.34 | M2: 0.51 | N2: 6.87 | O2: 358.25 | P2: 26.99 | Q2: 0 | R2: =IF(A2<>"",IF(A2="Total","",A2),"") -> Scott Okano | S2: =IF(AND(D2<>"",A2<>"Total"),1,0) -> 1 | T2: =IF(S2=1, DATE(YEAR(Settings!$B$3), MONTH(D2), DAY(D2)), "") -> 46272 | U2: =IF(S2=1,IFERROR(INDEX(Settings!$B$12:$B$41,MATCH($B2,Settings!$A$12:$A$41,0)),"N"),"") -> N | V2: =IF(S2=1,IFERROR(INDEX(Settings!$C$12:$C$41,MATCH($B2,Settings!$A$12:$A$41,0)),""),"") -> % of Tips | W2: =IF(S2=1,IFERROR(INDEX(Settings!$D$12:$D$41,MATCH($B2,Settings!$A$12:$A$41,0)),0),0) -> 0 | X2: =IF(AND(S2=1,U2="Y"),IF(V2="% of Sales",O2*W2,IF(V2="% of Tips",P2*W2,0)),0) -> 0 | Y2: =IF(S2=1,P2-X2,"") -> 26.99 | Z2: =IF(S2=1,IFERROR(INDEX(Settings!$E$12:$E$41,MATCH($B2,Settings!$A$12:$A$41,0)),"N"),"") -> Y | AA2: =IF(S2=1,IFERROR(INDEX(Settings!$F$12:$F$41,MATCH($B2,Settings!$A$12:$A$41,0)),0),0) -> 1 | AB2: =IF(S2=1,IFERROR(INDEX(Settings!$G$12:$G$41,MATCH($B2,Settings!$A$12:$A$41,0)),0),0) -> 1 | AC2: =IF(S2=1,SUMIFS($X$2:$X$601,$S$2:$S$601,1,$T$2:$T$601,T2),"") -> 303.99 | AD2: =IF(S2=1,SUMIFS($N$2:$N$601,$S$2:$S$601,1,$T$2:$T$601,T2,$B$2:$B$601,B2),"") -> 25.3 | AE2: =IF(S2=1,SUMIFS($N$2:$N$601,$S$2:$S$601,1,$T$2:$T$601,T2,$Z$2:$Z$601,"Y"),"") -> 25.3 | AF2: =IF(S2=1,SUMPRODUCT(($S$2:$S$601=1)*($T$2:$T$601=T2)*($Z$2:$Z$601="Y")*($N$2:$N$601)*($AB$2:$AB$601)),"") -> 25.3 | AG2: =IF(AND(S2=1,Z2="Y"),IF(Settings!$B$6="Percentage",IF(AD2=0,0,AC2*AA2*(N2/AD2)),IF(Settings!$B$6="Points",IF(AF2=0,0,AC2*(N2*AB2)/AF2),IF(Settings!$B$6="Equally",IF(AE2=0,0,AC2*N2/AE2),0))),0) -> 82.545901 | AH2: =IF(S2=1,Y2+AG2,"") -> 109.5359 | AI2: =IF(S2=1,IF(COUNTIFS($R$2:R2,R2,$S$2:S2,1)=1,1,0),0) -> 1 | AJ2: =SUM($AI$2:AI2) -> 1 | AL2: =IF(S2=1,SUMIF(D2:D67,D2,P2:P67)) -> 124.31
B3: Barista | C3: 19.75 | D3: 46274 | E3: 0.38125 | G3: 0.46180556 | H3: 1.92 | I3: 0 | J3: 0 | L3: 0 | M3: 0 | N3: 1.92 | O3: 142.5 | P3: 11.68 | Q3: 0 | R3: =IF(A3<>"",IF(A3="Total","",A3),IF(D3<>"",R2,"")) -> Scott Okano | S3: =IF(AND(D3<>"",A3<>"Total"),1,0) -> 1 | T3: =IF(S3=1, DATE(YEAR(Settings!$B$3), MONTH(D3), DAY(D3)), "") -> 46274 | U3: =IF(S3=1,IFERROR(INDEX(Settings!$B$12:$B$41,MATCH($B3,Settings!$A$12:$A$41,0)),"N"),"") -> N | V3: =IF(S3=1,IFERROR(INDEX(Settings!$C$12:$C$41,MATCH($B3,Settings!$A$12:$A$41,0)),""),"") -> % of Tips | W3: =IF(S3=1,IFERROR(INDEX(Settings!$D$12:$D$41,MATCH($B3,Settings!$A$12:$A$41,0)),0),0) -> 0 | X3: =IF(AND(S3=1,U3="Y"),IF(V3="% of Sales",O3*W3,IF(V3="% of Tips",P3*W3,0)),0) -> 0 | Y3: =IF(S3=1,P3-X3,"") -> 11.68 | Z3: =IF(S3=1,IFERROR(INDEX(Settings!$E$12:$E$41,MATCH($B3,Settings!$A$12:$A$41,0)),"N"),"") -> Y | AA3: =IF(S3=1,IFERROR(INDEX(Settings!$F$12:$F$41,MATCH($B3,Settings!$A$12:$A$41,0)),0),0) -> 1 | AB3: =IF(S3=1,IFERROR(INDEX(Settings!$G$12:$G$41,MATCH($B3,Settings!$A$12:$A$41,0)),0),0) -> 1 | AC3: =IF(S3=1,SUMIFS($X$2:$X$601,$S$2:$S$601,1,$T$2:$T$601,T3),"") -> 104.42 | AD3: =IF(S3=1,SUMIFS($N$2:$N$601,$S$2:$S$601,1,$T$2:$T$601,T3,$B$2:$B$601,B3),"") -> 10.98 | AE3: =IF(S3=1,SUMIFS($N$2:$N$601,$S$2:$S$601,1,$T$2:$T$601,T3,$Z$2:$Z$601,"Y"),"") -> 10.98 | AF3: =IF(S3=1,SUMPRODUCT(($S$2:$S$601=1)*($T$2:$T$601=T3)*($Z$2:$Z$601="Y")*($N$2:$N$601)*($AB$2:$AB$601)),"") -> 10.98 | AG3: =IF(AND(S3=1,Z3="Y"),IF(Settings!$B$6="Percentage",IF(AD3=0,0,AC3*AA3*(N3/AD3)),IF(Settings!$B$6="Points",IF(AF3=0,0,AC3*(N3*AB3)/AF3),IF(Settings!$B$6="Equally",IF(AE3=0,0,AC3*N3/AE3),0))),0) -> 18.259235 | AH3: =IF(S3=1,Y3+AG3,"") -> 29.939235 | AI3: =IF(S3=1,IF(COUNTIFS($R$2:R3,R3,$S$2:S3,1)=1,1,0),0) -> 0 | AJ3: =SUM($AI$2:AI3) -> 1
B4: Barista | C4: 19.75 | D4: 46274 | E4: 0.53888889 | G4: 0.74722222 | H4: 4.49 | I4: 0 | J4: 0 | L4: 0.17 | M4: 0.5 | N4: 4.49 | O4: 211 | P4: 19.66 | Q4: 0 | R4: =IF(A4<>"",IF(A4="Total","",A4),IF(D4<>"",R3,"")) -> Scott Okano | S4: =IF(AND(D4<>"",A4<>"Total"),1,0) -> 1 | T4: =IF(S4=1, DATE(YEAR(Settings!$B$3), MONTH(D4), DAY(D4)), "") -> 46274 | U4: =IF(S4=1,IFERROR(INDEX(Settings!$B$12:$B$41,MATCH($B4,Settings!$A$12:$A$41,0)),"N"),"") -> N | V4: =IF(S4=1,IFERROR(INDEX(Settings!$C$12:$C$41,MATCH($B4,Settings!$A$12:$A$41,0)),""),"") -> % of Tips | W4: =IF(S4=1,IFERROR(INDEX(Settings!$D$12:$D$41,MATCH($B4,Settings!$A$12:$A$41,0)),0),0) -> 0 | X4: =IF(AND(S4=1,U4="Y"),IF(V4="% of Sales",O4*W4,IF(V4="% of Tips",P4*W4,0)),0) -> 0 | Y4: =IF(S4=1,P4-X4,"") -> 19.66 | Z4: =IF(S4=1,IFERROR(INDEX(Settings!$E$12:$E$41,MATCH($B4,Settings!$A$12:$A$41,0)),"N"),"") -> Y | AA4: =IF(S4=1,IFERROR(INDEX(Settings!$F$12:$F$41,MATCH($B4,Settings!$A$12:$A$41,0)),0),0) -> 1 | AB4: =IF(S4=1,IFERROR(INDEX(Settings!$G$12:$G$41,MATCH($B4,Settings!$A$12:$A$41,0)),0),0) -> 1 | AC4: =IF(S4=1,SUMIFS($X$2:$X$601,$S$2:$S$601,1,$T$2:$T$601,T4),"") -> 104.42 | AD4: =IF(S4=1,SUMIFS($N$2:$N$601,$S$2:$S$601,1,$T$2:$T$601,T4,$B$2:$B$601,B4),"") -> 10.98 | AE4: =IF(S4=1,SUMIFS($N$2:$N$601,$S$2:$S$601,1,$T$2:$T$601,T4,$Z$2:$Z$601,"Y"),"") -> 10.98 | AF4: =IF(S4=1,SUMPRODUCT(($S$2:$S$601=1)*($T$2:$T$601=T4)*($Z$2:$Z$601="Y")*($N$2:$N$601)*($AB$2:$AB$601)),"") -> 10.98 | AG4: =IF(AND(S4=1,Z4="Y"),IF(Settings!$B$6="Percentage",IF(AD4=0,0,AC4*AA4*(N4/AD4)),IF(Settings!$B$6="Points",IF(AF4=0,0,AC4*(N4*AB4)/AF4),IF(Settings!$B$6="Equally",IF(AE4=0,0,AC4*N4/AE4),0))),0) -> 42.699982 | AH4: =IF(S4=1,Y4+AG4,"") -> 62.359982 | AI4: =IF(S4=1,IF(COUNTIFS($R$2:R4,R4,$S$2:S4,1)=1,1,0),0) -> 0 | AJ4: =SUM($AI$2:AI4) -> 1
B5: Barista | C5: 19.75 | D5: 46276 | E5: 0.52083333 | G5: 0.76180556 | H5: 5.3 | I5: 0 | J5: 0 | L5: 0.17 | M5: 0.5 | N5: 5.3 | O5: 227.31 | P5: 23.53 | Q5: 0 | R5: =IF(A5<>"",IF(A5="Total","",A5),IF(D5<>"",R4,"")) -> Scott Okano | S5: =IF(AND(D5<>"",A5<>"Total"),1,0) -> 1 | T5: =IF(S5=1, DATE(YEAR(Settings!$B$3), MONTH(D5), DAY(D5)), "") -> 46276 | U5: =IF(S5=1,IFERROR(INDEX(Settings!$B$12:$B$41,MATCH($B5,Settings!$A$12:$A$41,0)),"N"),"") -> N | V5: =IF(S5=1,IFERROR(INDEX(Settings!$C$12:$C$41,MATCH($B5,Settings!$A$12:$A$41,0)),""),"") -> % of Tips | W5: =IF(S5=1,IFERROR(INDEX(Settings!$D$12:$D$41,MATCH($B5,Settings!$A$12:$A$41,0)),0),0) -> 0 | X5: =IF(AND(S5=1,U5="Y"),IF(V5="% of Sales",O5*W5,IF(V5="% of Tips",P5*W5,0)),0) -> 0 | Y5: =IF(S5=1,P5-X5,"") -> 23.53 | Z5: =IF(S5=1,IFERROR(INDEX(Settings!$E$12:$E$41,MATCH($B5,Settings!$A$12:$A$41,0)),"N"),"") -> Y | AA5: =IF(S5=1,IFERROR(INDEX(Settings!$F$12:$F$41,MATCH($B5,Settings!$A$12:$A$41,0)),0),0) -> 1 | AB5: =IF(S5=1,IFERROR(INDEX(Settings!$G$12:$G$41,MATCH($B5,Settings!$A$12:$A$41,0)),0),0) -> 1 | AC5: =IF(S5=1,SUMIFS($X$2:$X$601,$S$2:$S$601,1,$T$2:$T$601,T5),"") -> 87.71 | AD5: =IF(S5=1,SUMIFS($N$2:$N$601,$S$2:$S$601,1,$T$2:$T$601,T5,$B$2:$B$601,B5),"") -> 15.74 | AE5: =IF(S5=1,SUMIFS($N$2:$N$601,$S$2:$S$601,1,$T$2:$T$601,T5,$Z$2:$Z$601,"Y"),"") -> 15.74 | AF5: =IF(S5=1,SUMPRODUCT(($S$2:$S$601=1)*($T$2:$T$601=T5)*($Z$2:$Z$601="Y")*($N$2:$N$601)*($AB$2:$AB$601)),"") -> 15.74 | AG5: =IF(AND(S5=1,Z5="Y"),IF(Settings!$B$6="Percentage",IF(AD5=0,0,AC5*AA5*(N5/AD5)),IF(Settings!$B$6="Points",IF(AF5=0,0,AC5*(N5*AB5)/AF5),IF(Settings!$B$6="Equally",IF(AE5=0,0,AC5*N5/AE5),0))),0) -> 29.533863 | AH5: =IF(S5=1,Y5+AG5,"") -> 53.063863 | AI5: =IF(S5=1,IF(COUNTIFS($R$2:R5,R5,$S$2:S5,1)=1,1,0),0) -> 0 | AJ5: =SUM($AI$2:AI5) -> 1
B6: Barista | C6: 19.75 | D6: 46279 | E6: 0.39652778 | G6: 0.72083333 | H6: 7.23 | I6: 0 | J6: 0 | L6: 0.34 | M6: 0.54 | N6: 7.23 | O6: 476.56 | P6: 42.29 | Q6: 0 | R6: =IF(A6<>"",IF(A6="Total","",A6),IF(D6<>"",R5,"")) -> Scott Okano | S6: =IF(AND(D6<>"",A6<>"Total"),1,0) -> 1 | T6: =IF(S6=1, DATE(YEAR(Settings!$B$3), MONTH(D6), DAY(D6)), "") -> 46279 | U6: =IF(S6=1,IFERROR(INDEX(Settings!$B$12:$B$41,MATCH($B6,Settings!$A$12:$A$41,0)),"N"),"") -> N | V6: =IF(S6=1,IFERROR(INDEX(Settings!$C$12:$C$41,MATCH($B6,Settings!$A$12:$A$41,0)),""),"") -> % of Tips | W6: =IF(S6=1,IFERROR(INDEX(Settings!$D$12:$D$41,MATCH($B6,Settings!$A$12:$A$41,0)),0),0) -> 0 | X6: =IF(AND(S6=1,U6="Y"),IF(V6="% of Sales",O6*W6,IF(V6="% of Tips",P6*W6,0)),0) -> 0 | Y6: =IF(S6=1,P6-X6,"") -> 42.29 | Z6: =IF(S6=1,IFERROR(INDEX(Settings!$E$12:$E$41,MATCH($B6,Settings!$A$12:$A$41,0)),"N"),"") -> Y | AA6: =IF(S6=1,IFERROR(INDEX(Settings!$F$12:$F$41,MATCH($B6,Settings!$A$12:$A$41,0)),0),0) -> 1 | AB6: =IF(S6=1,IFERROR(INDEX(Settings!$G$12:$G$41,MATCH($B6,Settings!$A$12:$A$41,0)),0),0) -> 1 | AC6: =IF(S6=1,SUMIFS($X$2:$X$601,$S$2:$S$601,1,$T$2:$T$601,T6),"") -> 80.03 | AD6: =IF(S6=1,SUMIFS($N$2:$N$601,$S$2:$S$601,1,$T$2:$T$601,T6,$B$2:$B$601,B6),"") -> 7.23 | AE6: =IF(S6=1,SUMIFS($N$2:$N$601,$S$2:$S$601,1,$T$2:$T$601,T6,$Z$2:$Z$601,"Y"),"") -> 7.23 | AF6: =IF(S6=1,SUMPRODUCT(($S$2:$S$601=1)*($T$2:$T$601=T6)*($Z$2:$Z$601="Y")*($N$2:$N$601)*($AB$2:$AB$601)),"") -> 7.23 | AG6: =IF(AND(S6=1,Z6="Y"),IF(Settings!$B$6="Percentage",IF(AD6=0,0,AC6*AA6*(N6/AD6)),IF(Settings!$B$6="Points",IF(AF6=0,0,AC6*(N6*AB6)/AF6),IF(Settings!$B$6="Equally",IF(AE6=0,0,AC6*N6/AE6),0))),0) -> 80.03 | AH6: =IF(S6=1,Y6+AG6,"") -> 122.32 | AI6: =IF(S6=1,IF(COUNTIFS($R$2:R6,R6,$S$2:S6,1)=1,1,0),0) -> 0 | AJ6: =SUM($AI$2:AI6) -> 1
B7: Barista | C7: 19.75 | D7: 46281 | E7: 0.5625 | G7: 0.74166667 | H7: 4.3 | I7: 0 | J7: 0 | L7: 0.17 | M7: 0 | N7: 4.3 | O7: 207.8 | P7: 21.6 | Q7: 0 | R7: =IF(A7<>"",IF(A7="Total","",A7),IF(D7<>"",R6,"")) -> Scott Okano | S7: =IF(AND(D7<>"",A7<>"Total"),1,0) -> 1 | T7: =IF(S7=1, DATE(YEAR(Settings!$B$3), MONTH(D7), DAY(D7)), "") -> 46281 | U7: =IF(S7=1,IFERROR(INDEX(Settings!$B$12:$B$41,MATCH($B7,Settings!$A$12:$A$41,0)),"N"),"") -> N | V7: =IF(S7=1,IFERROR(INDEX(Settings!$C$12:$C$41,MATCH($B7,Settings!$A$12:$A$41,0)),""),"") -> % of Tips | W7: =IF(S7=1,IFERROR(INDEX(Settings!$D$12:$D$41,MATCH($B7,Settings!$A$12:$A$41,0)),0),0) -> 0 | X7: =IF(AND(S7=1,U7="Y"),IF(V7="% of Sales",O7*W7,IF(V7="% of Tips",P7*W7,0)),0) -> 0 | Y7: =IF(S7=1,P7-X7,"") -> 21.6 | Z7: =IF(S7=1,IFERROR(INDEX(Settings!$E$12:$E$41,MATCH($B7,Settings!$A$12:$A$41,0)),"N"),"") -> Y | AA7: =IF(S7=1,IFERROR(INDEX(Settings!$F$12:$F$41,MATCH($B7,Settings!$A$12:$A$41,0)),0),0) -> 1 | AB7: =IF(S7=1,IFERROR(INDEX(Settings!$G$12:$G$41,MATCH($B7,Settings!$A$12:$A$41,0)),0),0) -> 1 | AC7: =IF(S7=1,SUMIFS($X$2:$X$601,$S$2:$S$601,1,$T$2:$T$601,T7),"") -> 81.58 | AD7: =IF(S7=1,SUMIFS($N$2:$N$601,$S$2:$S$601,1,$T$2:$T$601,T7,$B$2:$B$601,B7),"") -> 8.65 | AE7: =IF(S7=1,SUMIFS($N$2:$N$601,$S$2:$S$601,1,$T$2:$T$601,T7,$Z$2:$Z$601,"Y"),"") -> 8.65 | AF7: =IF(S7=1,SUMPRODUCT(($S$2:$S$601=1)*($T$2:$T$601=T7)*($Z$2:$Z$601="Y")*($N$2:$N$601)*($AB$2:$AB$601)),"") -> 8.65 | AG7: =IF(AND(S7=1,Z7="Y"),IF(Settings!$B$6="Percentage",IF(AD7=0,0,AC7*AA7*(N7/AD7)),IF(Settings!$B$6="Points",IF(AF7=0,0,AC7*(N7*AB7)/AF7),IF(Settings!$B$6="Equally",IF(AE7=0,0,AC7*N7/AE7),0))),0) -> 40.55422 | AH7: =IF(S7=1,Y7+AG7,"") -> 62.15422 | AI7: =IF(S7=1,IF(COUNTIFS($R$2:R7,R7,$S$2:S7,1)=1,1,0),0) -> 0 | AJ7: =SUM($AI$2:AI7) -> 1
B8: Barista | C8: 19.75 | D8: 46283 | E8: 0.58333333 | G8: 0.76805556 | H8: 4.43 | I8: 0 | J8: 0 | L8: 0.17 | M8: 0 | N8: 4.43 | O8: 248.35 | P8: 21.26 | Q8: 0 | R8: =IF(A8<>"",IF(A8="Total","",A8),IF(D8<>"",R7,"")) -> Scott Okano | S8: =IF(AND(D8<>"",A8<>"Total"),1,0) -> 1 | T8: =IF(S8=1, DATE(YEAR(Settings!$B$3), MONTH(D8), DAY(D8)), "") -> 46283 | U8: =IF(S8=1,IFERROR(INDEX(Settings!$B$12:$B$41,MATCH($B8,Settings!$A$12:$A$41,0)),"N"),"") -> N | V8: =IF(S8=1,IFERROR(INDEX(Settings!$C$12:$C$41,MATCH($B8,Settings!$A$12:$A$41,0)),""),"") -> % of Tips | W8: =IF(S8=1,IFERROR(INDEX(Settings!$D$12:$D$41,MATCH($B8,Settings!$A$12:$A$41,0)),0),0) -> 0 | X8: =IF(AND(S8=1,U8="Y"),IF(V8="% of Sales",O8*W8,IF(V8="% of Tips",P8*W8,0)),0) -> 0 | Y8: =IF(S8=1,P8-X8,"") -> 21.26 | Z8: =IF(S8=1,IFERROR(INDEX(Settings!$E$12:$E$41,MATCH($B8,Settings!$A$12:$A$41,0)),"N"),"") -> Y | AA8: =IF(S8=1,IFERROR(INDEX(Settings!$F$12:$F$41,MATCH($B8,Settings!$A$12:$A$41,0)),0),0) -> 1 | AB8: =IF(S8=1,IFERROR(INDEX(Settings!$G$12:$G$41,MATCH($B8,Settings!$A$12:$A$41,0)),0),0) -> 1 | AC8: =IF(S8=1,SUMIFS($X$2:$X$601,$S$2:$S$601,1,$T$2:$T$601,T8),"") -> 84.09 | AD8: =IF(S8=1,SUMIFS($N$2:$N$601,$S$2:$S$601,1,$T$2:$T$601,T8,$B$2:$B$601,B8),"") -> 12.5 | AE8: =IF(S8=1,SUMIFS($N$2:$N$601,$S$2:$S$601,1,$T$2:$T$601,T8,$Z$2:$Z$601,"Y"),"") -> 12.5 | AF8: =IF(S8=1,SUMPRODUCT(($S$2:$S$601=1)*($T$2:$T$601=T8)*($Z$2:$Z$601="Y")*($N$2:$N$601)*($AB$2:$AB$601)),"") -> 12.5 | AG8: =IF(AND(S8=1,Z8="Y"),IF(Settings!$B$6="Percentage",IF(AD8=0,0,AC8*AA8*(N8/AD8)),IF(Settings!$B$6="Points",IF(AF8=0,0,AC8*(N8*AB8)/AF8),IF(Settings!$B$6="Equally",IF(AE8=0,0,AC8*N8/AE8),0))),0) -> 29.801496 | AH8: =IF(S8=1,Y8+AG8,"") -> 51.061496 | AI8: =IF(S8=1,IF(COUNTIFS($R$2:R8,R8,$S$2:S8,1)=1,1,0),0) -> 0 | AJ8: =SUM($AI$2:AI8) -> 1
B9: Barista | C9: 19.75 | D9: 46284 | E9: 0.41597222 | G9: 0.70972222 | H9: 6.54 | I9: 0 | J9: 0 | L9: 0.34 | M9: 0.51 | N9: 6.54 | O9: 1276.42 | P9: 77.4 | Q9: 0 | R9: =IF(A9<>"",IF(A9="Total","",A9),IF(D9<>"",R8,"")) -> Scott Okano | S9: =IF(AND(D9<>"",A9<>"Total"),1,0) -> 1 | T9: =IF(S9=1, DATE(YEAR(Settings!$B$3), MONTH(D9), DAY(D9)), "") -> 46284 | U9: =IF(S9=1,IFERROR(INDEX(Settings!$B$12:$B$41,MATCH($B9,Settings!$A$12:$A$41,0)),"N"),"") -> N | V9: =IF(S9=1,IFERROR(INDEX(Settings!$C$12:$C$41,MATCH($B9,Settings!$A$12:$A$41,0)),""),"") -> % of Tips | W9: =IF(S9=1,IFERROR(INDEX(Settings!$D$12:$D$41,MATCH($B9,Settings!$A$12:$A$41,0)),0),0) -> 0 | X9: =IF(AND(S9=1,U9="Y"),IF(V9="% of Sales",O9*W9,IF(V9="% of Tips",P9*W9,0)),0) -> 0 | Y9: =IF(S9=1,P9-X9,"") -> 77.4 | Z9: =IF(S9=1,IFERROR(INDEX(Settings!$E$12:$E$41,MATCH($B9,Settings!$A$12:$A$41,0)),"N"),"") -> Y | AA9: =IF(S9=1,IFERROR(INDEX(Settings!$F$12:$F$41,MATCH($B9,Settings!$A$12:$A$41,0)),0),0) -> 1 | AB9: =IF(S9=1,IFERROR(INDEX(Settings!$G$12:$G$41,MATCH($B9,Settings!$A$12:$A$41,0)),0),0) -> 1 | AC9: =IF(S9=1,SUMIFS($X$2:$X$601,$S$2:$S$601,1,$T$2:$T$601,T9),"") -> 190.57 | AD9: =IF(S9=1,SUMIFS($N$2:$N$601,$S$2:$S$601,1,$T$2:$T$601,T9,$B$2:$B$601,B9),"") -> 28 | AE9: =IF(S9=1,SUMIFS($N$2:$N$601,$S$2:$S$601,1,$T$2:$T$601,T9,$Z$2:$Z$601,"Y"),"") -> 28 | AF9: =IF(S9=1,SUMPRODUCT(($S$2:$S$601=1)*($T$2:$T$601=T9)*($Z$2:$Z$601="Y")*($N$2:$N$601)*($AB$2:$AB$601)),"") -> 28 | AG9: =IF(AND(S9=1,Z9="Y"),IF(Settings!$B$6="Percentage",IF(AD9=0,0,AC9*AA9*(N9/AD9)),IF(Settings!$B$6="Points",IF(AF9=0,0,AC9*(N9*AB9)/AF9),IF(Settings!$B$6="Equally",IF(AE9=0,0,AC9*N9/AE9),0))),0) -> 44.511707 | AH9: =IF(S9=1,Y9+AG9,"") -> 121.91171 | AI9: =IF(S9=1,IF(COUNTIFS($R$2:R9,R9,$S$2:S9,1)=1,1,0),0) -> 0 | AJ9: =SUM($AI$2:AI9) -> 1
A10: Total | H10: 41.08 | I10: 0 | J10: 0 | K10: 0 | L10: 1.7 | M10: 2.56 | N10: 41.08 | O10: 3148.19 | P10: 244.41 | Q10: 0 | R10: =IF(A10<>"",IF(A10="Total","",A10),IF(D10<>"",R9,"")) | S10: =IF(AND(D10<>"",A10<>"Total"),1,0) -> 0 | T10: =IF(S10=1, DATE(YEAR(Settings!$B$3), MONTH(D10), DAY(D10)), "") | U10: =IF(S10=1,IFERROR(INDEX(Settings!$B$12:$B$41,MATCH($B10,Settings!$A$12:$A$41,0)),"N"),"") | V10: =IF(S10=1,IFERROR(INDEX(Settings!$C$12:$C$41,MATCH($B10,Settings!$A$12:$A$41,0)),""),"") | W10: =IF(S10=1,IFERROR(INDEX(Settings!$D$12:$D$41,MATCH($B10,Settings!$A$12:$A$41,0)),0),0) -> 0 | X10: =IF(AND(S10=1,U10="Y"),IF(V10="% of Sales",O10*W10,IF(V10="% of Tips",P10*W10,0)),0) -> 0 | Y10: =IF(S10=1,P10-X10,"") | Z10: =IF(S10=1,IFERROR(INDEX(Settings!$E$12:$E$41,MATCH($B10,Settings!$A$12:$A$41,0)),"N"),"") | AA10: =IF(S10=1,IFERROR(INDEX(Settings!$F$12:$F$41,MATCH($B10,Settings!$A$12:$A$41,0)),0),0) -> 0 | AB10: =IF(S10=1,IFERROR(INDEX(Settings!$G$12:$G$41,MATCH($B10,Settings!$A$12:$A$41,0)),0),0) -> 0 | AC10: =IF(S10=1,SUMIFS($X$2:$X$601,$S$2:$S$601,1,$T$2:$T$601,T10),"") | AD10: =IF(S10=1,SUMIFS($N$2:$N$601,$S$2:$S$601,1,$T$2:$T$601,T10,$B$2:$B$601,B10),"") | AE10: =IF(S10=1,SUMIFS($N$2:$N$601,$S$2:$S$601,1,$T$2:$T$601,T10,$Z$2:$Z$601,"Y"),"") | AF10: =IF(S10=1,SUMPRODUCT(($S$2:$S$601=1)*($T$2:$T$601=T10)*($Z$2:$Z$601="Y")*($N$2:$N$601)*($AB$2:$AB$601)),"") | AG10: =IF(AND(S10=1,Z10="Y"),IF(Settings!$B$6="Percentage",IF(AD10=0,0,AC10*AA10*(N10/AD10)),IF(Settings!$B$6="Points",IF(AF10=0,0,AC10*(N10*AB10)/AF10),IF(Settings!$B$6="Equally",IF(AE10=0,0,AC10*N10/AE10),0))),0) -> 0 | AH10: =IF(S10=1,Y10+AG10,"") | AI10: =IF(S10=1,IF(COUNTIFS($R$2:R10,R10,$S$2:S10,1)=1,1,0),0) -> 0 | AJ10: =SUM($AI$2:AI10) -> 1
R11: =IF(A11<>"",IF(A11="Total","",A11),IF(D11<>"",R10,"")) | S11: =IF(AND(D11<>"",A11<>"Total"),1,0) -> 0 | T11: =IF(S11=1, DATE(YEAR(Settings!$B$3), MONTH(D11), DAY(D11)), "") | U11: =IF(S11=1,IFERROR(INDEX(Settings!$B$12:$B$41,MATCH($B11,Settings!$A$12:$A$41,0)),"N"),"") | V11: =IF(S11=1,IFERROR(INDEX(Settings!$C$12:$C$41,MATCH($B11,Settings!$A$12:$A$41,0)),""),"") | W11: =IF(S11=1,IFERROR(INDEX(Settings!$D$12:$D$41,MATCH($B11,Settings!$A$12:$A$41,0)),0),0) -> 0 | X11: =IF(AND(S11=1,U11="Y"),IF(V11="% of Sales",O11*W11,IF(V11="% of Tips",P11*W11,0)),0) -> 0 | Y11: =IF(S11=1,P11-X11,"") | Z11: =IF(S11=1,IFERROR(INDEX(Settings!$E$12:$E$41,MATCH($B11,Settings!$A$12:$A$41,0)),"N"),"") | AA11: =IF(S11=1,IFERROR(INDEX(Settings!$F$12:$F$41,MATCH($B11,Settings!$A$12:$A$41,0)),0),0) -> 0 | AB11: =IF(S11=1,IFERROR(INDEX(Settings!$G$12:$G$41,MATCH($B11,Settings!$A$12:$A$41,0)),0),0) -> 0 | AC11: =IF(S11=1,SUMIFS($X$2:$X$601,$S$2:$S$601,1,$T$2:$T$601,T11),"") | AD11: =IF(S11=1,SUMIFS($N$2:$N$601,$S$2:$S$601,1,$T$2:$T$601,T11,$B$2:$B$601,B11),"") | AE11: =IF(S11=1,SUMIFS($N$2:$N$601,$S$2:$S$601,1,$T$2:$T$601,T11,$Z$2:$Z$601,"Y"),"") | AF11: =IF(S11=1,SUMPRODUCT(($S$2:$S$601=1)*($T$2:$T$601=T11)*($Z$2:$Z$601="Y")*($N$2:$N$601)*($AB$2:$AB$601)),"") | AG11: =IF(AND(S11=1,Z11="Y"),IF(Settings!$B$6="Percentage",IF(AD11=0,0,AC11*AA11*(N11/AD11)),IF(Settings!$B$6="Points",IF(AF11=0,0,AC11*(N11*AB11)/AF11),IF(Settings!$B$6="Equally",IF(AE11=0,0,AC11*N11/AE11),0))),0) -> 0 | AH11: =IF(S11=1,Y11+AG11,"") | AI11: =IF(S11=1,IF(COUNTIFS($R$2:R11,R11,$S$2:S11,1)=1,1,0),0) -> 0 | AJ11: =SUM($AI$2:AI11) -> 1
A12: Shamira Tesorero | B12: Barista | C12: 19.61 | D12: 46278 | E12: 0.41597222 | G12: 0.70486111 | H12: 6.42 | I12: 0 | J12: 0 | L12: 0.17 | M12: 0.52 | N12: 6.42 | O12: 1498.08 | P12: 117.29 | Q12: 0 | R12: =IF(A12<>"",IF(A12="Total","",A12),IF(D12<>"",R11,"")) -> Shamira Tesorero | S12: =IF(AND(D12<>"",A12<>"Total"),1,0) -> 1 | T12: =IF(S12=1, DATE(YEAR(Settings!$B$3), MONTH(D12), DAY(D12)), "") -> 46278 | U12: =IF(S12=1,IFERROR(INDEX(Settings!$B$12:$B$41,MATCH($B12,Settings!$A$12:$A$41,0)),"N"),"") -> N | V12: =IF(S12=1,IFERROR(INDEX(Settings!$C$12:$C$41,MATCH($B12,Settings!$A$12:$A$41,0)),""),"") -> % of Tips | W12: =IF(S12=1,IFERROR(INDEX(Settings!$D$12:$D$41,MATCH($B12,Settings!$A$12:$A$41,0)),0),0) -> 0 | X12: =IF(AND(S12=1,U12="Y"),IF(V12="% of Sales",O12*W12,IF(V12="% of Tips",P12*W12,0)),0) -> 0 | Y12: =IF(S12=1,P12-X12,"") -> 117.29 | Z12: =IF(S12=1,IFERROR(INDEX(Settings!$E$12:$E$41,MATCH($B12,Settings!$A$12:$A$41,0)),"N"),"") -> Y | AA12: =IF(S12=1,IFERROR(INDEX(Settings!$F$12:$F$41,MATCH($B12,Settings!$A$12:$A$41,0)),0),0) -> 1 | AB12: =IF(S12=1,IFERROR(INDEX(Settings!$G$12:$G$41,MATCH($B12,Settings!$A$12:$A$41,0)),0),0) -> 1 | AC12: =IF(S12=1,SUMIFS($X$2:$X$601,$S$2:$S$601,1,$T$2:$T$601,T12),"") -> 242.76 | AD12: =IF(S12=1,SUMIFS($N$2:$N$601,$S$2:$S$601,1,$T$2:$T$601,T12,$B$2:$B$601,B12),"") -> 20.37 | AE12: =IF(S12=1,SUMIFS($N$2:$N$601,$S$2:$S$601,1,$T$2:$T$601,T12,$Z$2:$Z$601,"Y"),"") -> 20.37 | AF12: =IF(S12=1,SUMPRODUCT(($S$2:$S$601=1)*($T$2:$T$601=T12)*($Z$2:$Z$601="Y")*($N$2:$N$601)*($AB$2:$AB$601)),"") -> 20.37 | AG12: =IF(AND(S12=1,Z12="Y"),IF(Settings!$B$6="Percentage",IF(AD12=0,0,AC12*AA12*(N12/AD12)),IF(Settings!$B$6="Points",IF(AF12=0,0,AC12*(N12*AB12)/AF12),IF(Settings!$B$6="Equally",IF(AE12=0,0,AC12*N12/AE12),0))),0) -> 76.510515 | AH12: =IF(S12=1,Y12+AG12,"") -> 193.80052 | AI12: =IF(S12=1,IF(COUNTIFS($R$2:R12,R12,$S$2:S12,1)=1,1,0),0) -> 1 | AJ12: =SUM($AI$2:AI12) -> 2
B13: Barista | C13: 19.61 | D13: 46284 | E13: 0.39513889 | G13: 0.62986111 | H13: 5.06 | I13: 0 | J13: 0 | L13: 0.17 | M13: 0.59 | N13: 5.06 | O13: 412.2 | P13: 42.71 | Q13: 0 | R13: =IF(A13<>"",IF(A13="Total","",A13),IF(D13<>"",R12,"")) -> Shamira Tesorero | S13: =IF(AND(D13<>"",A13<>"Total"),1,0) -> 1 | T13: =IF(S13=1, DATE(YEAR(Settings!$B$3), MONTH(D13), DAY(D13)), "") -> 46284 | U13: =IF(S13=1,IFERROR(INDEX(Settings!$B$12:$B$41,MATCH($B13,Settings!$A$12:$A$41,0)),"N"),"") -> N | V13: =IF(S13=1,IFERROR(INDEX(Settings!$C$12:$C$41,MATCH($B13,Settings!$A$12:$A$41,0)),""),"") -> % of Tips | W13: =IF(S13=1,IFERROR(INDEX(Settings!$D$12:$D$41,MATCH($B13,Settings!$A$12:$A$41,0)),0),0) -> 0 | X13: =IF(AND(S13=1,U13="Y"),IF(V13="% of Sales",O13*W13,IF(V13="% of Tips",P13*W13,0)),0) -> 0 | Y13: =IF(S13=1,P13-X13,"") -> 42.71 | Z13: =IF(S13=1,IFERROR(INDEX(Settings!$E$12:$E$41,MATCH($B13,Settings!$A$12:$A$41,0)),"N"),"") -> Y | AA13: =IF(S13=1,IFERROR(INDEX(Settings!$F$12:$F$41,MATCH($B13,Settings!$A$12:$A$41,0)),0),0) -> 1 | AB13: =IF(S13=1,IFERROR(INDEX(Settings!$G$12:$G$41,MATCH($B13,Settings!$A$12:$A$41,0)),0),0) -> 1 | AC13: =IF(S13=1,SUMIFS($X$2:$X$601,$S$2:$S$601,1,$T$2:$T$601,T13),"") -> 190.57 | AD13: =IF(S13=1,SUMIFS($N$2:$N$601,$S$2:$S$601,1,$T$2:$T$601,T13,$B$2:$B$601,B13),"") -> 28 | AE13: =IF(S13=1,SUMIFS($N$2:$N$601,$S$2:$S$601,1,$T$2:$T$601,T13,$Z$2:$Z$601,"Y"),"") -> 28 | AF13: =IF(S13=1,SUMPRODUCT(($S$2:$S$601=1)*($T$2:$T$601=T13)*($Z$2:$Z$601="Y")*($N$2:$N$601)*($AB$2:$AB$601)),"") -> 28 | AG13: =IF(AND(S13=1,Z13="Y"),IF(Settings!$B$6="Percentage",IF(AD13=0,0,AC13*AA13*(N13/AD13)),IF(Settings!$B$6="Points",IF(AF13=0,0,AC13*(N13*AB13)/AF13),IF(Settings!$B$6="Equally",IF(AE13=0,0,AC13*N13/AE13),0))),0) -> 34.438721 | AH13: =IF(S13=1,Y13+AG13,"") -> 77.148721 | AI13: =IF(S13=1,IF(COUNTIFS($R$2:R13,R13,$S$2:S13,1)=1,1,0),0) -> 0 | AJ13: =SUM($AI$2:AI13) -> 2
B14: Barista | C14: 19.61 | D14: 46285 | E14: 0.41319444 | G14: 0.71111111 | H14: 6.65 | I14: 0 | J14: 0 | L14: 0.34 | M14: 0.51 | N14: 6.65 | O14: 858.77 | P14: 66.56 | Q14: 0 | R14: =IF(A14<>"",IF(A14="Total","",A14),IF(D14<>"",R13,"")) -> Shamira Tesorero | S14: =IF(AND(D14<>"",A14<>"Total"),1,0) -> 1 | T14: =IF(S14=1, DATE(YEAR(Settings!$B$3), MONTH(D14), DAY(D14)), "") -> 46285 | U14: =IF(S14=1,IFERROR(INDEX(Settings!$B$12:$B$41,MATCH($B14,Settings!$A$12:$A$41,0)),"N"),"") -> N | V14: =IF(S14=1,IFERROR(INDEX(Settings!$C$12:$C$41,MATCH($B14,Settings!$A$12:$A$41,0)),""),"") -> % of Tips | W14: =IF(S14=1,IFERROR(INDEX(Settings!$D$12:$D$41,MATCH($B14,Settings!$A$12:$A$41,0)),0),0) -> 0 | X14: =IF(AND(S14=1,U14="Y"),IF(V14="% of Sales",O14*W14,IF(V14="% of Tips",P14*W14,0)),0) -> 0 | Y14: =IF(S14=1,P14-X14,"") -> 66.56 | Z14: =IF(S14=1,IFERROR(INDEX(Settings!$E$12:$E$41,MATCH($B14,Settings!$A$12:$A$41,0)),"N"),"") -> Y | AA14: =IF(S14=1,IFERROR(INDEX(Settings!$F$12:$F$41,MATCH($B14,Settings!$A$12:$A$41,0)),0),0) -> 1 | AB14: =IF(S14=1,IFERROR(INDEX(Settings!$G$12:$G$41,MATCH($B14,Settings!$A$12:$A$41,0)),0),0) -> 1 | AC14: =IF(S14=1,SUMIFS($X$2:$X$601,$S$2:$S$601,1,$T$2:$T$601,T14),"") -> 146.5 | AD14: =IF(S14=1,SUMIFS($N$2:$N$601,$S$2:$S$601,1,$T$2:$T$601,T14,$B$2:$B$601,B14),"") -> 22.34 | AE14: =IF(S14=1,SUMIFS($N$2:$N$601,$S$2:$S$601,1,$T$2:$T$601,T14,$Z$2:$Z$601,"Y"),"") -> 22.34 | AF14: =IF(S14=1,SUMPRODUCT(($S$2:$S$601=1)*($T$2:$T$601=T14)*($Z$2:$Z$601="Y")*($N$2:$N$601)*($AB$2:$AB$601)),"") -> 22.34 | AG14: =IF(AND(S14=1,Z14="Y"),IF(Settings!$B$6="Percentage",IF(AD14=0,0,AC14*AA14*(N14/AD14)),IF(Settings!$B$6="Points",IF(AF14=0,0,AC14*(N14*AB14)/AF14),IF(Settings!$B$6="Equally",IF(AE14=0,0,AC14*N14/AE14),0))),0) -> 43.608997 | AH14: =IF(S14=1,Y14+AG14,"") -> 110.169 | AI14: =IF(S14=1,IF(COUNTIFS($R$2:R14,R14,$S$2:S14,1)=1,1,0),0) -> 0 | AJ14: =SUM($AI$2:AI14) -> 2
A15: Total | H15: 18.13 | I15: 0 | J15: 0 | K15: 0 | L15: 0.68 | M15: 1.62 | N15: 18.13 | O15: 2769.05 | P15: 226.56 | Q15: 0 | R15: =IF(A15<>"",IF(A15="Total","",A15),IF(D15<>"",R14,"")) | S15: =IF(AND(D15<>"",A15<>"Total"),1,0) -> 0 | T15: =IF(S15=1, DATE(YEAR(Settings!$B$3), MONTH(D15), DAY(D15)), "") | U15: =IF(S15=1,IFERROR(INDEX(Settings!$B$12:$B$41,MATCH($B15,Settings!$A$12:$A$41,0)),"N"),"") | V15: =IF(S15=1,IFERROR(INDEX(Settings!$C$12:$C$41,MATCH($B15,Settings!$A$12:$A$41,0)),""),"") | W15: =IF(S15=1,IFERROR(INDEX(Settings!$D$12:$D$41,MATCH($B15,Settings!$A$12:$A$41,0)),0),0) -> 0 | X15: =IF(AND(S15=1,U15="Y"),IF(V15="% of Sales",O15*W15,IF(V15="% of Tips",P15*W15,0)),0) -> 0 | Y15: =IF(S15=1,P15-X15,"") | Z15: =IF(S15=1,IFERROR(INDEX(Settings!$E$12:$E$41,MATCH($B15,Settings!$A$12:$A$41,0)),"N"),"") | AA15: =IF(S15=1,IFERROR(INDEX(Settings!$F$12:$F$41,MATCH($B15,Settings!$A$12:$A$41,0)),0),0) -> 0 | AB15: =IF(S15=1,IFERROR(INDEX(Settings!$G$12:$G$41,MATCH($B15,Settings!$A$12:$A$41,0)),0),0) -> 0 | AC15: =IF(S15=1,SUMIFS($X$2:$X$601,$S$2:$S$601,1,$T$2:$T$601,T15),"") | AD15: =IF(S15=1,SUMIFS($N$2:$N$601,$S$2:$S$601,1,$T$2:$T$601,T15,$B$2:$B$601,B15),"") | AE15: =IF(S15=1,SUMIFS($N$2:$N$601,$S$2:$S$601,1,$T$2:$T$601,T15,$Z$2:$Z$601,"Y"),"") | AF15: =IF(S15=1,SUMPRODUCT(($S$2:$S$601=1)*($T$2:$T$601=T15)*($Z$2:$Z$601="Y")*($N$2:$N$601)*($AB$2:$AB$601)),"") | AG15: =IF(AND(S15=1,Z15="Y"),IF(Settings!$B$6="Percentage",IF(AD15=0,0,AC15*AA15*(N15/AD15)),IF(Settings!$B$6="Points",IF(AF15=0,0,AC15*(N15*AB15)/AF15),IF(Settings!$B$6="Equally",IF(AE15=0,0,AC15*N15/AE15),0))),0) -> 0 | AH15: =IF(S15=1,Y15+AG15,"") | AI15: =IF(S15=1,IF(COUNTIFS($R$2:R15,R15,$S$2:S15,1)=1,1,0),0) -> 0 | AJ15: =SUM($AI$2:AI15) -> 2
R16: =IF(A16<>"",IF(A16="Total","",A16),IF(D16<>"",R15,"")) | S16: =IF(AND(D16<>"",A16<>"Total"),1,0) -> 0 | T16: =IF(S16=1, DATE(YEAR(Settings!$B$3), MONTH(D16), DAY(D16)), "") | U16: =IF(S16=1,IFERROR(INDEX(Settings!$B$12:$B$41,MATCH($B16,Settings!$A$12:$A$41,0)),"N"),"") | V16: =IF(S16=1,IFERROR(INDEX(Settings!$C$12:$C$41,MATCH($B16,Settings!$A$12:$A$41,0)),""),"") | W16: =IF(S16=1,IFERROR(INDEX(Settings!$D$12:$D$41,MATCH($B16,Settings!$A$12:$A$41,0)),0),0) -> 0 | X16: =IF(AND(S16=1,U16="Y"),IF(V16="% of Sales",O16*W16,IF(V16="% of Tips",P16*W16,0)),0) -> 0 | Y16: =IF(S16=1,P16-X16,"") | Z16: =IF(S16=1,IFERROR(INDEX(Settings!$E$12:$E$41,MATCH($B16,Settings!$A$12:$A$41,0)),"N"),"") | AA16: =IF(S16=1,IFERROR(INDEX(Settings!$F$12:$F$41,MATCH($B16,Settings!$A$12:$A$41,0)),0),0) -> 0 | AB16: =IF(S16=1,IFERROR(INDEX(Settings!$G$12:$G$41,MATCH($B16,Settings!$A$12:$A$41,0)),0),0) -> 0 | AC16: =IF(S16=1,SUMIFS($X$2:$X$601,$S$2:$S$601,1,$T$2:$T$601,T16),"") | AD16: =IF(S16=1,SUMIFS($N$2:$N$601,$S$2:$S$601,1,$T$2:$T$601,T16,$B$2:$B$601,B16),"") | AE16: =IF(S16=1,SUMIFS($N$2:$N$601,$S$2:$S$601,1,$T$2:$T$601,T16,$Z$2:$Z$601,"Y"),"") | AF16: =IF(S16=1,SUMPRODUCT(($S$2:$S$601=1)*($T$2:$T$601=T16)*($Z$2:$Z$601="Y")*($N$2:$N$601)*($AB$2:$AB$601)),"") | AG16: =IF(AND(S16=1,Z16="Y"),IF(Settings!$B$6="Percentage",IF(AD16=0,0,AC16*AA16*(N16/AD16)),IF(Settings!$B$6="Points",IF(AF16=0,0,AC16*(N16*AB16)/AF16),IF(Settings!$B$6="Equally",IF(AE16=0,0,AC16*N16/AE16),0))),0) -> 0 | AH16: =IF(S16=1,Y16+AG16,"") | AI16: =IF(S16=1,IF(COUNTIFS($R$2:R16,R16,$S$2:S16,1)=1,1,0),0) -> 0 | AJ16: =SUM($AI$2:AI16) -> 2
A17: Tessa Andrascik | B17: Barista | C17: 19.61 | D17: 46282 | E17: 0.39861111 | G17: 0.56805556 | H17: 4.03 | I17: 0 | J17: 0 | L17: 0.17 | M17: 0.03 | N17: 4.03 | O17: 276 | P17: 20.32 | Q17: 0 | R17: =IF(A17<>"",IF(A17="Total","",A17),IF(D17<>"",R16,"")) -> Tessa Andrascik | S17: =IF(AND(D17<>"",A17<>"Total"),1,0) -> 1 | T17: =IF(S17=1, DATE(YEAR(Settings!$B$3), MONTH(D17), DAY(D17)), "") -> 46282 | U17: =IF(S17=1,IFERROR(INDEX(Settings!$B$12:$B$41,MATCH($B17,Settings!$A$12:$A$41,0)),"N"),"") -> N | V17: =IF(S17=1,IFERROR(INDEX(Settings!$C$12:$C$41,MATCH($B17,Settings!$A$12:$A$41,0)),""),"") -> % of Tips | W17: =IF(S17=1,IFERROR(INDEX(Settings!$D$12:$D$41,MATCH($B17,Settings!$A$12:$A$41,0)),0),0) -> 0 | X17: =IF(AND(S17=1,U17="Y"),IF(V17="% of Sales",O17*W17,IF(V17="% of Tips",P17*W17,0)),0) -> 0 | Y17: =IF(S17=1,P17-X17,"") -> 20.32 | Z17: =IF(S17=1,IFERROR(INDEX(Settings!$E$12:$E$41,MATCH($B17,Settings!$A$12:$A$41,0)),"N"),"") -> Y | AA17: =IF(S17=1,IFERROR(INDEX(Settings!$F$12:$F$41,MATCH($B17,Settings!$A$12:$A$41,0)),0),0) -> 1 | AB17: =IF(S17=1,IFERROR(INDEX(Settings!$G$12:$G$41,MATCH($B17,Settings!$A$12:$A$41,0)),0),0) -> 1 | AC17: =IF(S17=1,SUMIFS($X$2:$X$601,$S$2:$S$601,1,$T$2:$T$601,T17),"") -> 72.78 | AD17: =IF(S17=1,SUMIFS($N$2:$N$601,$S$2:$S$601,1,$T$2:$T$601,T17,$B$2:$B$601,B17),"") -> 8.07 | AE17: =IF(S17=1,SUMIFS($N$2:$N$601,$S$2:$S$601,1,$T$2:$T$601,T17,$Z$2:$Z$601,"Y"),"") -> 8.07 | AF17: =IF(S17=1,SUMPRODUCT(($S$2:$S$601=1)*($T$2:$T$601=T17)*($Z$2:$Z$601="Y")*($N$2:$N$601)*($AB$2:$AB$601)),"") -> 8.07 | AG17: =IF(AND(S17=1,Z17="Y"),IF(Settings!$B$6="Percentage",IF(AD17=0,0,AC17*AA17*(N17/AD17)),IF(Settings!$B$6="Points",IF(AF17=0,0,AC17*(N17*AB17)/AF17),IF(Settings!$B$6="Equally",IF(AE17=0,0,AC17*N17/AE17),0))),0) -> 36.344907 | AH17: =IF(S17=1,Y17+AG17,"") -> 56.664907 | AI17: =IF(S17=1,IF(COUNTIFS($R$2:R17,R17,$S$2:S17,1)=1,1,0),0) -> 1 | AJ17: =SUM($AI$2:AI17) -> 3
B18: Barista | C18: 19.61 | D18: 46283 | E18: 0.47986111 | G18: 0.625 | H18: 3.49 | I18: 0 | J18: 0 | L18: 0.17 | M18: 0 | N18: 3.49 | O18: 509 | P18: 40.15 | Q18: 0 | R18: =IF(A18<>"",IF(A18="Total","",A18),IF(D18<>"",R17,"")) -> Tessa Andrascik | S18: =IF(AND(D18<>"",A18<>"Total"),1,0) -> 1 | T18: =IF(S18=1, DATE(YEAR(Settings!$B$3), MONTH(D18), DAY(D18)), "") -> 46283 | U18: =IF(S18=1,IFERROR(INDEX(Settings!$B$12:$B$41,MATCH($B18,Settings!$A$12:$A$41,0)),"N"),"") -> N | V18: =IF(S18=1,IFERROR(INDEX(Settings!$C$12:$C$41,MATCH($B18,Settings!$A$12:$A$41,0)),""),"") -> % of Tips | W18: =IF(S18=1,IFERROR(INDEX(Settings!$D$12:$D$41,MATCH($B18,Settings!$A$12:$A$41,0)),0),0) -> 0 | X18: =IF(AND(S18=1,U18="Y"),IF(V18="% of Sales",O18*W18,IF(V18="% of Tips",P18*W18,0)),0) -> 0 | Y18: =IF(S18=1,P18-X18,"") -> 40.15 | Z18: =IF(S18=1,IFERROR(INDEX(Settings!$E$12:$E$41,MATCH($B18,Settings!$A$12:$A$41,0)),"N"),"") -> Y | AA18: =IF(S18=1,IFERROR(INDEX(Settings!$F$12:$F$41,MATCH($B18,Settings!$A$12:$A$41,0)),0),0) -> 1 | AB18: =IF(S18=1,IFERROR(INDEX(Settings!$G$12:$G$41,MATCH($B18,Settings!$A$12:$A$41,0)),0),0) -> 1 | AC18: =IF(S18=1,SUMIFS($X$2:$X$601,$S$2:$S$601,1,$T$2:$T$601,T18),"") -> 84.09 | AD18: =IF(S18=1,SUMIFS($N$2:$N$601,$S$2:$S$601,1,$T$2:$T$601,T18,$B$2:$B$601,B18),"") -> 12.5 | AE18: =IF(S18=1,SUMIFS($N$2:$N$601,$S$2:$S$601,1,$T$2:$T$601,T18,$Z$2:$Z$601,"Y"),"") -> 12.5 | AF18: =IF(S18=1,SUMPRODUCT(($S$2:$S$601=1)*($T$2:$T$601=T18)*($Z$2:$Z$601="Y")*($N$2:$N$601)*($AB$2:$AB$601)),"") -> 12.5 | AG18: =IF(AND(S18=1,Z18="Y"),IF(Settings!$B$6="Percentage",IF(AD18=0,0,AC18*AA18*(N18/AD18)),IF(Settings!$B$6="Points",IF(AF18=0,0,AC18*(N18*AB18)/AF18),IF(Settings!$B$6="Equally",IF(AE18=0,0,AC18*N18/AE18),0))),0) -> 23.477928 | AH18: =IF(S18=1,Y18+AG18,"") -> 63.627928 | AI18: =IF(S18=1,IF(COUNTIFS($R$2:R18,R18,$S$2:S18,1)=1,1,0),0) -> 0 | AJ18: =SUM($AI$2:AI18) -> 3
A19: Total | H19: 7.52 | I19: 0 | J19: 0 | K19: 0 | L19: 0.34 | M19: 0.03 | N19: 7.52 | O19: 785 | P19: 60.47 | Q19: 0 | R19: =IF(A19<>"",IF(A19="Total","",A19),IF(D19<>"",R18,"")) | S19: =IF(AND(D19<>"",A19<>"Total"),1,0) -> 0 | T19: =IF(S19=1, DATE(YEAR(Settings!$B$3), MONTH(D19), DAY(D19)), "") | U19: =IF(S19=1,IFERROR(INDEX(Settings!$B$12:$B$41,MATCH($B19,Settings!$A$12:$A$41,0)),"N"),"") | V19: =IF(S19=1,IFERROR(INDEX(Settings!$C$12:$C$41,MATCH($B19,Settings!$A$12:$A$41,0)),""),"") | W19: =IF(S19=1,IFERROR(INDEX(Settings!$D$12:$D$41,MATCH($B19,Settings!$A$12:$A$41,0)),0),0) -> 0 | X19: =IF(AND(S19=1,U19="Y"),IF(V19="% of Sales",O19*W19,IF(V19="% of Tips",P19*W19,0)),0) -> 0 | Y19: =IF(S19=1,P19-X19,"") | Z19: =IF(S19=1,IFERROR(INDEX(Settings!$E$12:$E$41,MATCH($B19,Settings!$A$12:$A$41,0)),"N"),"") | AA19: =IF(S19=1,IFERROR(INDEX(Settings!$F$12:$F$41,MATCH($B19,Settings!$A$12:$A$41,0)),0),0) -> 0 | AB19: =IF(S19=1,IFERROR(INDEX(Settings!$G$12:$G$41,MATCH($B19,Settings!$A$12:$A$41,0)),0),0) -> 0 | AC19: =IF(S19=1,SUMIFS($X$2:$X$601,$S$2:$S$601,1,$T$2:$T$601,T19),"") | AD19: =IF(S19=1,SUMIFS($N$2:$N$601,$S$2:$S$601,1,$T$2:$T$601,T19,$B$2:$B$601,B19),"") | AE19: =IF(S19=1,SUMIFS($N$2:$N$601,$S$2:$S$601,1,$T$2:$T$601,T19,$Z$2:$Z$601,"Y"),"") | AF19: =IF(S19=1,SUMPRODUCT(($S$2:$S$601=1)*($T$2:$T$601=T19)*($Z$2:$Z$601="Y")*($N$2:$N$601)*($AB$2:$AB$601)),"") | AG19: =IF(AND(S19=1,Z19="Y"),IF(Settings!$B$6="Percentage",IF(AD19=0,0,AC19*AA19*(N19/AD19)),IF(Settings!$B$6="Points",IF(AF19=0,0,AC19*(N19*AB19)/AF19),IF(Settings!$B$6="Equally",IF(AE19=0,0,AC19*N19/AE19),0))),0) -> 0 | AH19: =IF(S19=1,Y19+AG19,"") | AI19: =IF(S19=1,IF(COUNTIFS($R$2:R19,R19,$S$2:S19,1)=1,1,0),0) -> 0 | AJ19: =SUM($AI$2:AI19) -> 3
R20: =IF(A20<>"",IF(A20="Total","",A20),IF(D20<>"",R19,"")) | S20: =IF(AND(D20<>"",A20<>"Total"),1,0) -> 0 | T20: =IF(S20=1, DATE(YEAR(Settings!$B$3), MONTH(D20), DAY(D20)), "") | U20: =IF(S20=1,IFERROR(INDEX(Settings!$B$12:$B$41,MATCH($B20,Settings!$A$12:$A$41,0)),"N"),"") | V20: =IF(S20=1,IFERROR(INDEX(Settings!$C$12:$C$41,MATCH($B20,Settings!$A$12:$A$41,0)),""),"") | W20: =IF(S20=1,IFERROR(INDEX(Settings!$D$12:$D$41,MATCH($B20,Settings!$A$12:$A$41,0)),0),0) -> 0 | X20: =IF(AND(S20=1,U20="Y"),IF(V20="% of Sales",O20*W20,IF(V20="% of Tips",P20*W20,0)),0) -> 0 | Y20: =IF(S20=1,P20-X20,"") | Z20: =IF(S20=1,IFERROR(INDEX(Settings!$E$12:$E$41,MATCH($B20,Settings!$A$12:$A$41,0)),"N"),"") | AA20: =IF(S20=1,IFERROR(INDEX(Settings!$F$12:$F$41,MATCH($B20,Settings!$A$12:$A$41,0)),0),0) -> 0 | AB20: =IF(S20=1,IFERROR(INDEX(Settings!$G$12:$G$41,MATCH($B20,Settings!$A$12:$A$41,0)),0),0) -> 0 | AC20: =IF(S20=1,SUMIFS($X$2:$X$601,$S$2:$S$601,1,$T$2:$T$601,T20),"") | AD20: =IF(S20=1,SUMIFS($N$2:$N$601,$S$2:$S$601,1,$T$2:$T$601,T20,$B$2:$B$601,B20),"") | AE20: =IF(S20=1,SUMIFS($N$2:$N$601,$S$2:$S$601,1,$T$2:$T$601,T20,$Z$2:$Z$601,"Y"),"") | AF20: =IF(S20=1,SUMPRODUCT(($S$2:$S$601=1)*($T$2:$T$601=T20)*($Z$2:$Z$601="Y")*($N$2:$N$601)*($AB$2:$AB$601)),"") | AG20: =IF(AND(S20=1,Z20="Y"),IF(Settings!$B$6="Percentage",IF(AD20=0,0,AC20*AA20*(N20/AD20)),IF(Settings!$B$6="Points",IF(AF20=0,0,AC20*(N20*AB20)/AF20),IF(Settings!$B$6="Equally",IF(AE20=0,0,AC20*N20/AE20),0))),0) -> 0 | AH20: =IF(S20=1,Y20+AG20,"") | AI20: =IF(S20=1,IF(COUNTIFS($R$2:R20,R20,$S$2:S20,1)=1,1,0),0) -> 0 | AJ20: =SUM($AI$2:AI20) -> 3
A21: Anthony Zhang | B21: Barista | C21: 19.61 | D21: 46272 | E21: 0.49583333 | G21: 0.73263889 | H21: 5.67 | I21: 0 | J21: 0 | L21: 0.17 | M21: 0.01 | N21: 5.67 | O21: 0 | P21: 0 | Q21: 0 | R21: =IF(A21<>"",IF(A21="Total","",A21),IF(D21<>"",R20,"")) -> Anthony Zhang | S21: =IF(AND(D21<>"",A21<>"Total"),1,0) -> 1 | T21: =IF(S21=1, DATE(YEAR(Settings!$B$3), MONTH(D21), DAY(D21)), "") -> 46272 | U21: =IF(S21=1,IFERROR(INDEX(Settings!$B$12:$B$41,MATCH($B21,Settings!$A$12:$A$41,0)),"N"),"") -> N | V21: =IF(S21=1,IFERROR(INDEX(Settings!$C$12:$C$41,MATCH($B21,Settings!$A$12:$A$41,0)),""),"") -> % of Tips | W21: =IF(S21=1,IFERROR(INDEX(Settings!$D$12:$D$41,MATCH($B21,Settings!$A$12:$A$41,0)),0),0) -> 0 | X21: =IF(AND(S21=1,U21="Y"),IF(V21="% of Sales",O21*W21,IF(V21="% of Tips",P21*W21,0)),0) -> 0 | Y21: =IF(S21=1,P21-X21,"") -> 0 | Z21: =IF(S21=1,IFERROR(INDEX(Settings!$E$12:$E$41,MATCH($B21,Settings!$A$12:$A$41,0)),"N"),"") -> Y | AA21: =IF(S21=1,IFERROR(INDEX(Settings!$F$12:$F$41,MATCH($B21,Settings!$A$12:$A$41,0)),0),0) -> 1 | AB21: =IF(S21=1,IFERROR(INDEX(Settings!$G$12:$G$41,MATCH($B21,Settings!$A$12:$A$41,0)),0),0) -> 1 | AC21: =IF(S21=1,SUMIFS($X$2:$X$601,$S$2:$S$601,1,$T$2:$T$601,T21),"") -> 303.99 | AD21: =IF(S21=1,SUMIFS($N$2:$N$601,$S$2:$S$601,1,$T$2:$T$601,T21,$B$2:$B$601,B21),"") -> 25.3 | AE21: =IF(S21=1,SUMIFS($N$2:$N$601,$S$2:$S$601,1,$T$2:$T$601,T21,$Z$2:$Z$601,"Y"),"") -> 25.3 | AF21: =IF(S21=1,SUMPRODUCT(($S$2:$S$601=1)*($T$2:$T$601=T21)*($Z$2:$Z$601="Y")*($N$2:$N$601)*($AB$2:$AB$601)),"") -> 25.3 | AG21: =IF(AND(S21=1,Z21="Y"),IF(Settings!$B$6="Percentage",IF(AD21=0,0,AC21*AA21*(N21/AD21)),IF(Settings!$B$6="Points",IF(AF21=0,0,AC21*(N21*AB21)/AF21),IF(Settings!$B$6="Equally",IF(AE21=0,0,AC21*N21/AE21),0))),0) -> 68.127403 | AH21: =IF(S21=1,Y21+AG21,"") -> 68.127403 | AI21: =IF(S21=1,IF(COUNTIFS($R$2:R21,R21,$S$2:S21,1)=1,1,0),0) -> 1 | AJ21: =SUM($AI$2:AI21) -> 4
B22: Barista | C22: 19.61 | D22: 46276 | E22: 0.44791667 | G22: 0.6625 | H22: 5.14 | I22: 0 | J22: 0 | L22: 0.31 | M22: 0.02 | N22: 5.14 | O22: 226.56 | P22: 19.77 | Q22: 0 | R22: =IF(A22<>"",IF(A22="Total","",A22),IF(D22<>"",R21,"")) -> Anthony Zhang | S22: =IF(AND(D22<>"",A22<>"Total"),1,0) -> 1 | T22: =IF(S22=1, DATE(YEAR(Settings!$B$3), MONTH(D22), DAY(D22)), "") -> 46276 | U22: =IF(S22=1,IFERROR(INDEX(Settings!$B$12:$B$41,MATCH($B22,Settings!$A$12:$A$41,0)),"N"),"") -> N | V22: =IF(S22=1,IFERROR(INDEX(Settings!$C$12:$C$41,MATCH($B22,Settings!$A$12:$A$41,0)),""),"") -> % of Tips | W22: =IF(S22=1,IFERROR(INDEX(Settings!$D$12:$D$41,MATCH($B22,Settings!$A$12:$A$41,0)),0),0) -> 0 | X22: =IF(AND(S22=1,U22="Y"),IF(V22="% of Sales",O22*W22,IF(V22="% of Tips",P22*W22,0)),0) -> 0 | Y22: =IF(S22=1,P22-X22,"") -> 19.77 | Z22: =IF(S22=1,IFERROR(INDEX(Settings!$E$12:$E$41,MATCH($B22,Settings!$A$12:$A$41,0)),"N"),"") -> Y | AA22: =IF(S22=1,IFERROR(INDEX(Settings!$F$12:$F$41,MATCH($B22,Settings!$A$12:$A$41,0)),0),0) -> 1 | AB22: =IF(S22=1,IFERROR(INDEX(Settings!$G$12:$G$41,MATCH($B22,Settings!$A$12:$A$41,0)),0),0) -> 1 | AC22: =IF(S22=1,SUMIFS($X$2:$X$601,$S$2:$S$601,1,$T$2:$T$601,T22),"") -> 87.71 | AD22: =IF(S22=1,SUMIFS($N$2:$N$601,$S$2:$S$601,1,$T$2:$T$601,T22,$B$2:$B$601,B22),"") -> 15.74 | AE22: =IF(S22=1,SUMIFS($N$2:$N$601,$S$2:$S$601,1,$T$2:$T$601,T22,$Z$2:$Z$601,"Y"),"") -> 15.74 | AF22: =IF(S22=1,SUMPRODUCT(($S$2:$S$601=1)*($T$2:$T$601=T22)*($Z$2:$Z$601="Y")*($N$2:$N$601)*($AB$2:$AB$601)),"") -> 15.74 | AG22: =IF(AND(S22=1,Z22="Y"),IF(Settings!$B$6="Percentage",IF(AD22=0,0,AC22*AA22*(N22/AD22)),IF(Settings!$B$6="Points",IF(AF22=0,0,AC22*(N22*AB22)/AF22),IF(Settings!$B$6="Equally",IF(AE22=0,0,AC22*N22/AE22),0))),0) -> 28.642274 | AH22: =IF(S22=1,Y22+AG22,"") -> 48.412274 | AI22: =IF(S22=1,IF(COUNTIFS($R$2:R22,R22,$S$2:S22,1)=1,1,0),0) -> 0 | AJ22: =SUM($AI$2:AI22) -> 4
B23: Barista | C23: 19.61 | D23: 46277 | E23: 0.45069444 | G23: 0.75763889 | H23: 7.37 | I23: 0 | J23: 0 | L23: 0.32 | M23: 0 | N23: 7.37 | O23: 36 | P23: 3.13 | Q23: 0 | R23: =IF(A23<>"",IF(A23="Total","",A23),IF(D23<>"",R22,"")) -> Anthony Zhang | S23: =IF(AND(D23<>"",A23<>"Total"),1,0) -> 1 | T23: =IF(S23=1, DATE(YEAR(Settings!$B$3), MONTH(D23), DAY(D23)), "") -> 46277 | U23: =IF(S23=1,IFERROR(INDEX(Settings!$B$12:$B$41,MATCH($B23,Settings!$A$12:$A$41,0)),"N"),"") -> N | V23: =IF(S23=1,IFERROR(INDEX(Settings!$C$12:$C$41,MATCH($B23,Settings!$A$12:$A$41,0)),""),"") -> % of Tips | W23: =IF(S23=1,IFERROR(INDEX(Settings!$D$12:$D$41,MATCH($B23,Settings!$A$12:$A$41,0)),0),0) -> 0 | X23: =IF(AND(S23=1,U23="Y"),IF(V23="% of Sales",O23*W23,IF(V23="% of Tips",P23*W23,0)),0) -> 0 | Y23: =IF(S23=1,P23-X23,"") -> 3.13 | Z23: =IF(S23=1,IFERROR(INDEX(Settings!$E$12:$E$41,MATCH($B23,Settings!$A$12:$A$41,0)),"N"),"") -> Y | AA23: =IF(S23=1,IFERROR(INDEX(Settings!$F$12:$F$41,MATCH($B23,Settings!$A$12:$A$41,0)),0),0) -> 1 | AB23: =IF(S23=1,IFERROR(INDEX(Settings!$G$12:$G$41,MATCH($B23,Settings!$A$12:$A$41,0)),0),0) -> 1 | AC23: =IF(S23=1,SUMIFS($X$2:$X$601,$S$2:$S$601,1,$T$2:$T$601,T23),"") -> 220.79 | AD23: =IF(S23=1,SUMIFS($N$2:$N$601,$S$2:$S$601,1,$T$2:$T$601,T23,$B$2:$B$601,B23),"") -> 24.11 | AE23: =IF(S23=1,SUMIFS($N$2:$N$601,$S$2:$S$601,1,$T$2:$T$601,T23,$Z$2:$Z$601,"Y"),"") -> 24.11 | AF23: =IF(S23=1,SUMPRODUCT(($S$2:$S$601=1)*($T$2:$T$601=T23)*($Z$2:$Z$601="Y")*($N$2:$N$601)*($AB$2:$AB$601)),"") -> 24.11 | AG23: =IF(AND(S23=1,Z23="Y"),IF(Settings!$B$6="Percentage",IF(AD23=0,0,AC23*AA23*(N23/AD23)),IF(Settings!$B$6="Points",IF(AF23=0,0,AC23*(N23*AB23)/AF23),IF(Settings!$B$6="Equally",IF(AE23=0,0,AC23*N23/AE23),0))),0) -> 67.491593 | AH23: =IF(S23=1,Y23+AG23,"") -> 70.621593 | AI23: =IF(S23=1,IF(COUNTIFS($R$2:R23,R23,$S$2:S23,1)=1,1,0),0) -> 0 | AJ23: =SUM($AI$2:AI23) -> 4
B24: Barista | C24: 19.61 | D24: 46284 | E24: 0.54652778 | G24: 0.75902778 | H24: 5.08 | I24: 0 | J24: 0 | L24: 0.34 | M24: 0.03 | N24: 5.08 | O24: 37.6 | P24: 2.31 | Q24: 0 | R24: =IF(A24<>"",IF(A24="Total","",A24),IF(D24<>"",R23,"")) -> Anthony Zhang | S24: =IF(AND(D24<>"",A24<>"Total"),1,0) -> 1 | T24: =IF(S24=1, DATE(YEAR(Settings!$B$3), MONTH(D24), DAY(D24)), "") -> 46284 | U24: =IF(S24=1,IFERROR(INDEX(Settings!$B$12:$B$41,MATCH($B24,Settings!$A$12:$A$41,0)),"N"),"") -> N | V24: =IF(S24=1,IFERROR(INDEX(Settings!$C$12:$C$41,MATCH($B24,Settings!$A$12:$A$41,0)),""),"") -> % of Tips | W24: =IF(S24=1,IFERROR(INDEX(Settings!$D$12:$D$41,MATCH($B24,Settings!$A$12:$A$41,0)),0),0) -> 0 | X24: =IF(AND(S24=1,U24="Y"),IF(V24="% of Sales",O24*W24,IF(V24="% of Tips",P24*W24,0)),0) -> 0 | Y24: =IF(S24=1,P24-X24,"") -> 2.31 | Z24: =IF(S24=1,IFERROR(INDEX(Settings!$E$12:$E$41,MATCH($B24,Settings!$A$12:$A$41,0)),"N"),"") -> Y | AA24: =IF(S24=1,IFERROR(INDEX(Settings!$F$12:$F$41,MATCH($B24,Settings!$A$12:$A$41,0)),0),0) -> 1 | AB24: =IF(S24=1,IFERROR(INDEX(Settings!$G$12:$G$41,MATCH($B24,Settings!$A$12:$A$41,0)),0),0) -> 1 | AC24: =IF(S24=1,SUMIFS($X$2:$X$601,$S$2:$S$601,1,$T$2:$T$601,T24),"") -> 190.57 | AD24: =IF(S24=1,SUMIFS($N$2:$N$601,$S$2:$S$601,1,$T$2:$T$601,T24,$B$2:$B$601,B24),"") -> 28 | AE24: =IF(S24=1,SUMIFS($N$2:$N$601,$S$2:$S$601,1,$T$2:$T$601,T24,$Z$2:$Z$601,"Y"),"") -> 28 | AF24: =IF(S24=1,SUMPRODUCT(($S$2:$S$601=1)*($T$2:$T$601=T24)*($Z$2:$Z$601="Y")*($N$2:$N$601)*($AB$2:$AB$601)),"") -> 28 | AG24: =IF(AND(S24=1,Z24="Y"),IF(Settings!$B$6="Percentage",IF(AD24=0,0,AC24*AA24*(N24/AD24)),IF(Settings!$B$6="Points",IF(AF24=0,0,AC24*(N24*AB24)/AF24),IF(Settings!$B$6="Equally",IF(AE24=0,0,AC24*N24/AE24),0))),0) -> 34.574843 | AH24: =IF(S24=1,Y24+AG24,"") -> 36.884843 | AI24: =IF(S24=1,IF(COUNTIFS($R$2:R24,R24,$S$2:S24,1)=1,1,0),0) -> 0 | AJ24: =SUM($AI$2:AI24) -> 4
B25: Barista | C25: 19.61 | D25: 46285 | E25: 0.54236111 | G25: 0.76180556 | H25: 5.21 | I25: 0 | J25: 0 | L25: 0.3 | M25: 0.06 | N25: 5.21 | O25: 165.25 | P25: 10.29 | Q25: 0 | R25: =IF(A25<>"",IF(A25="Total","",A25),IF(D25<>"",R24,"")) -> Anthony Zhang | S25: =IF(AND(D25<>"",A25<>"Total"),1,0) -> 1 | T25: =IF(S25=1, DATE(YEAR(Settings!$B$3), MONTH(D25), DAY(D25)), "") -> 46285 | U25: =IF(S25=1,IFERROR(INDEX(Settings!$B$12:$B$41,MATCH($B25,Settings!$A$12:$A$41,0)),"N"),"") -> N | V25: =IF(S25=1,IFERROR(INDEX(Settings!$C$12:$C$41,MATCH($B25,Settings!$A$12:$A$41,0)),""),"") -> % of Tips | W25: =IF(S25=1,IFERROR(INDEX(Settings!$D$12:$D$41,MATCH($B25,Settings!$A$12:$A$41,0)),0),0) -> 0 | X25: =IF(AND(S25=1,U25="Y"),IF(V25="% of Sales",O25*W25,IF(V25="% of Tips",P25*W25,0)),0) -> 0 | Y25: =IF(S25=1,P25-X25,"") -> 10.29 | Z25: =IF(S25=1,IFERROR(INDEX(Settings!$E$12:$E$41,MATCH($B25,Settings!$A$12:$A$41,0)),"N"),"") -> Y | AA25: =IF(S25=1,IFERROR(INDEX(Settings!$F$12:$F$41,MATCH($B25,Settings!$A$12:$A$41,0)),0),0) -> 1 | AB25: =IF(S25=1,IFERROR(INDEX(Settings!$G$12:$G$41,MATCH($B25,Settings!$A$12:$A$41,0)),0),0) -> 1 | AC25: =IF(S25=1,SUMIFS($X$2:$X$601,$S$2:$S$601,1,$T$2:$T$601,T25),"") -> 146.5 | AD25: =IF(S25=1,SUMIFS($N$2:$N$601,$S$2:$S$601,1,$T$2:$T$601,T25,$B$2:$B$601,B25),"") -> 22.34 | AE25: =IF(S25=1,SUMIFS($N$2:$N$601,$S$2:$S$601,1,$T$2:$T$601,T25,$Z$2:$Z$601,"Y"),"") -> 22.34 | AF25: =IF(S25=1,SUMPRODUCT(($S$2:$S$601=1)*($T$2:$T$601=T25)*($Z$2:$Z$601="Y")*($N$2:$N$601)*($AB$2:$AB$601)),"") -> 22.34 | AG25: =IF(AND(S25=1,Z25="Y"),IF(Settings!$B$6="Percentage",IF(AD25=0,0,AC25*AA25*(N25/AD25)),IF(Settings!$B$6="Points",IF(AF25=0,0,AC25*(N25*AB25)/AF25),IF(Settings!$B$6="Equally",IF(AE25=0,0,AC25*N25/AE25),0))),0) -> 34.165846 | AH25: =IF(S25=1,Y25+AG25,"") -> 44.455846 | AI25: =IF(S25=1,IF(COUNTIFS($R$2:R25,R25,$S$2:S25,1)=1,1,0),0) -> 0 | AJ25: =SUM($AI$2:AI25) -> 4
A26: Total | H26: 28.47 | I26: 0 | J26: 0 | K26: 0 | L26: 1.44 | M26: 0.12 | N26: 28.47 | O26: 465.41 | P26: 35.5 | Q26: 0 | R26: =IF(A26<>"",IF(A26="Total","",A26),IF(D26<>"",R25,"")) | S26: =IF(AND(D26<>"",A26<>"Total"),1,0) -> 0 | T26: =IF(S26=1, DATE(YEAR(Settings!$B$3), MONTH(D26), DAY(D26)), "") | U26: =IF(S26=1,IFERROR(INDEX(Settings!$B$12:$B$41,MATCH($B26,Settings!$A$12:$A$41,0)),"N"),"") | V26: =IF(S26=1,IFERROR(INDEX(Settings!$C$12:$C$41,MATCH($B26,Settings!$A$12:$A$41,0)),""),"") | W26: =IF(S26=1,IFERROR(INDEX(Settings!$D$12:$D$41,MATCH($B26,Settings!$A$12:$A$41,0)),0),0) -> 0 | X26: =IF(AND(S26=1,U26="Y"),IF(V26="% of Sales",O26*W26,IF(V26="% of Tips",P26*W26,0)),0) -> 0 | Y26: =IF(S26=1,P26-X26,"") | Z26: =IF(S26=1,IFERROR(INDEX(Settings!$E$12:$E$41,MATCH($B26,Settings!$A$12:$A$41,0)),"N"),"") | AA26: =IF(S26=1,IFERROR(INDEX(Settings!$F$12:$F$41,MATCH($B26,Settings!$A$12:$A$41,0)),0),0) -> 0 | AB26: =IF(S26=1,IFERROR(INDEX(Settings!$G$12:$G$41,MATCH($B26,Settings!$A$12:$A$41,0)),0),0) -> 0 | AC26: =IF(S26=1,SUMIFS($X$2:$X$601,$S$2:$S$601,1,$T$2:$T$601,T26),"") | AD26: =IF(S26=1,SUMIFS($N$2:$N$601,$S$2:$S$601,1,$T$2:$T$601,T26,$B$2:$B$601,B26),"") | AE26: =IF(S26=1,SUMIFS($N$2:$N$601,$S$2:$S$601,1,$T$2:$T$601,T26,$Z$2:$Z$601,"Y"),"") | AF26: =IF(S26=1,SUMPRODUCT(($S$2:$S$601=1)*($T$2:$T$601=T26)*($Z$2:$Z$601="Y")*($N$2:$N$601)*($AB$2:$AB$601)),"") | AG26: =IF(AND(S26=1,Z26="Y"),IF(Settings!$B$6="Percentage",IF(AD26=0,0,AC26*AA26*(N26/AD26)),IF(Settings!$B$6="Points",IF(AF26=0,0,AC26*(N26*AB26)/AF26),IF(Settings!$B$6="Equally",IF(AE26=0,0,AC26*N26/AE26),0))),0) -> 0 | AH26: =IF(S26=1,Y26+AG26,"") | AI26: =IF(S26=1,IF(COUNTIFS($R$2:R26,R26,$S$2:S26,1)=1,1,0),0) -> 0 | AJ26: =SUM($AI$2:AI26) -> 4
R27: =IF(A27<>"",IF(A27="Total","",A27),IF(D27<>"",R26,"")) | S27: =IF(AND(D27<>"",A27<>"Total"),1,0) -> 0 | T27: =IF(S27=1, DATE(YEAR(Settings!$B$3), MONTH(D27), DAY(D27)), "") | U27: =IF(S27=1,IFERROR(INDEX(Settings!$B$12:$B$41,MATCH($B27,Settings!$A$12:$A$41,0)),"N"),"") | V27: =IF(S27=1,IFERROR(INDEX(Settings!$C$12:$C$41,MATCH($B27,Settings!$A$12:$A$41,0)),""),"") | W27: =IF(S27=1,IFERROR(INDEX(Settings!$D$12:$D$41,MATCH($B27,Settings!$A$12:$A$41,0)),0),0) -> 0 | X27: =IF(AND(S27=1,U27="Y"),IF(V27="% of Sales",O27*W27,IF(V27="% of Tips",P27*W27,0)),0) -> 0 | Y27: =IF(S27=1,P27-X27,"") | Z27: =IF(S27=1,IFERROR(INDEX(Settings!$E$12:$E$41,MATCH($B27,Settings!$A$12:$A$41,0)),"N"),"") | AA27: =IF(S27=1,IFERROR(INDEX(Settings!$F$12:$F$41,MATCH($B27,Settings!$A$12:$A$41,0)),0),0) -> 0 | AB27: =IF(S27=1,IFERROR(INDEX(Settings!$G$12:$G$41,MATCH($B27,Settings!$A$12:$A$41,0)),0),0) -> 0 | AC27: =IF(S27=1,SUMIFS($X$2:$X$601,$S$2:$S$601,1,$T$2:$T$601,T27),"") | AD27: =IF(S27=1,SUMIFS($N$2:$N$601,$S$2:$S$601,1,$T$2:$T$601,T27,$B$2:$B$601,B27),"") | AE27: =IF(S27=1,SUMIFS($N$2:$N$601,$S$2:$S$601,1,$T$2:$T$601,T27,$Z$2:$Z$601,"Y"),"") | AF27: =IF(S27=1,SUMPRODUCT(($S$2:$S$601=1)*($T$2:$T$601=T27)*($Z$2:$Z$601="Y")*($N$2:$N$601)*($AB$2:$AB$601)),"") | AG27: =IF(AND(S27=1,Z27="Y"),IF(Settings!$B$6="Percentage",IF(AD27=0,0,AC27*AA27*(N27/AD27)),IF(Settings!$B$6="Points",IF(AF27=0,0,AC27*(N27*AB27)/AF27),IF(Settings!$B$6="Equally",IF(AE27=0,0,AC27*N27/AE27),0))),0) -> 0 | AH27: =IF(S27=1,Y27+AG27,"") | AI27: =IF(S27=1,IF(COUNTIFS($R$2:R27,R27,$S$2:S27,1)=1,1,0),0) -> 0 | AJ27: =SUM($AI$2:AI27) -> 4
A28: Fatimah Mahmoud | B28: Barista | C28: 19.61 | D28: 46272 | E28: 0.54444444 | G28: 0.77083333 | H28: 5.42 | I28: 0 | J28: 0 | L28: 0.17 | M28: 0 | N28: 5.42 | O28: 0 | P28: 0 | Q28: 0 | R28: =IF(A28<>"",IF(A28="Total","",A28),IF(D28<>"",R27,"")) -> Fatimah Mahmoud | S28: =IF(AND(D28<>"",A28<>"Total"),1,0) -> 1 | T28: =IF(S28=1, DATE(YEAR(Settings!$B$3), MONTH(D28), DAY(D28)), "") -> 46272 | U28: =IF(S28=1,IFERROR(INDEX(Settings!$B$12:$B$41,MATCH($B28,Settings!$A$12:$A$41,0)),"N"),"") -> N | V28: =IF(S28=1,IFERROR(INDEX(Settings!$C$12:$C$41,MATCH($B28,Settings!$A$12:$A$41,0)),""),"") -> % of Tips | W28: =IF(S28=1,IFERROR(INDEX(Settings!$D$12:$D$41,MATCH($B28,Settings!$A$12:$A$41,0)),0),0) -> 0 | X28: =IF(AND(S28=1,U28="Y"),IF(V28="% of Sales",O28*W28,IF(V28="% of Tips",P28*W28,0)),0) -> 0 | Y28: =IF(S28=1,P28-X28,"") -> 0 | Z28: =IF(S28=1,IFERROR(INDEX(Settings!$E$12:$E$41,MATCH($B28,Settings!$A$12:$A$41,0)),"N"),"") -> Y | AA28: =IF(S28=1,IFERROR(INDEX(Settings!$F$12:$F$41,MATCH($B28,Settings!$A$12:$A$41,0)),0),0) -> 1 | AB28: =IF(S28=1,IFERROR(INDEX(Settings!$G$12:$G$41,MATCH($B28,Settings!$A$12:$A$41,0)),0),0) -> 1 | AC28: =IF(S28=1,SUMIFS($X$2:$X$601,$S$2:$S$601,1,$T$2:$T$601,T28),"") -> 303.99 | AD28: =IF(S28=1,SUMIFS($N$2:$N$601,$S$2:$S$601,1,$T$2:$T$601,T28,$B$2:$B$601,B28),"") -> 25.3 | AE28: =IF(S28=1,SUMIFS($N$2:$N$601,$S$2:$S$601,1,$T$2:$T$601,T28,$Z$2:$Z$601,"Y"),"") -> 25.3 | AF28: =IF(S28=1,SUMPRODUCT(($S$2:$S$601=1)*($T$2:$T$601=T28)*($Z$2:$Z$601="Y")*($N$2:$N$601)*($AB$2:$AB$601)),"") -> 25.3 | AG28: =IF(AND(S28=1,Z28="Y"),IF(Settings!$B$6="Percentage",IF(AD28=0,0,AC28*AA28*(N28/AD28)),IF(Settings!$B$6="Points",IF(AF28=0,0,AC28*(N28*AB28)/AF28),IF(Settings!$B$6="Equally",IF(AE28=0,0,AC28*N28/AE28),0))),0) -> 65.123549 | AH28: =IF(S28=1,Y28+AG28,"") -> 65.123549 | AI28: =IF(S28=1,IF(COUNTIFS($R$2:R28,R28,$S$2:S28,1)=1,1,0),0) -> 1 | AJ28: =SUM($AI$2:AI28) -> 5
B29: Barista | C29: 19.61 | D29: 46278 | E29: 0.54791667 | G29: 0.77430556 | H29: 5.43 | I29: 0 | J29: 0 | L29: 0.12 | M29: 0 | N29: 5.43 | O29: 733.6 | P29: 60.27 | Q29: 0 | R29: =IF(A29<>"",IF(A29="Total","",A29),IF(D29<>"",R28,"")) -> Fatimah Mahmoud | S29: =IF(AND(D29<>"",A29<>"Total"),1,0) -> 1 | T29: =IF(S29=1, DATE(YEAR(Settings!$B$3), MONTH(D29), DAY(D29)), "") -> 46278 | U29: =IF(S29=1,IFERROR(INDEX(Settings!$B$12:$B$41,MATCH($B29,Settings!$A$12:$A$41,0)),"N"),"") -> N | V29: =IF(S29=1,IFERROR(INDEX(Settings!$C$12:$C$41,MATCH($B29,Settings!$A$12:$A$41,0)),""),"") -> % of Tips | W29: =IF(S29=1,IFERROR(INDEX(Settings!$D$12:$D$41,MATCH($B29,Settings!$A$12:$A$41,0)),0),0) -> 0 | X29: =IF(AND(S29=1,U29="Y"),IF(V29="% of Sales",O29*W29,IF(V29="% of Tips",P29*W29,0)),0) -> 0 | Y29: =IF(S29=1,P29-X29,"") -> 60.27 | Z29: =IF(S29=1,IFERROR(INDEX(Settings!$E$12:$E$41,MATCH($B29,Settings!$A$12:$A$41,0)),"N"),"") -> Y | AA29: =IF(S29=1,IFERROR(INDEX(Settings!$F$12:$F$41,MATCH($B29,Settings!$A$12:$A$41,0)),0),0) -> 1 | AB29: =IF(S29=1,IFERROR(INDEX(Settings!$G$12:$G$41,MATCH($B29,Settings!$A$12:$A$41,0)),0),0) -> 1 | AC29: =IF(S29=1,SUMIFS($X$2:$X$601,$S$2:$S$601,1,$T$2:$T$601,T29),"") -> 242.76 | AD29: =IF(S29=1,SUMIFS($N$2:$N$601,$S$2:$S$601,1,$T$2:$T$601,T29,$B$2:$B$601,B29),"") -> 20.37 | AE29: =IF(S29=1,SUMIFS($N$2:$N$601,$S$2:$S$601,1,$T$2:$T$601,T29,$Z$2:$Z$601,"Y"),"") -> 20.37 | AF29: =IF(S29=1,SUMPRODUCT(($S$2:$S$601=1)*($T$2:$T$601=T29)*($Z$2:$Z$601="Y")*($N$2:$N$601)*($AB$2:$AB$601)),"") -> 20.37 | AG29: =IF(AND(S29=1,Z29="Y"),IF(Settings!$B$6="Percentage",IF(AD29=0,0,AC29*AA29*(N29/AD29)),IF(Settings!$B$6="Points",IF(AF29=0,0,AC29*(N29*AB29)/AF29),IF(Settings!$B$6="Equally",IF(AE29=0,0,AC29*N29/AE29),0))),0) -> 64.712165 | AH29: =IF(S29=1,Y29+AG29,"") -> 124.98216 | AI29: =IF(S29=1,IF(COUNTIFS($R$2:R29,R29,$S$2:S29,1)=1,1,0),0) -> 0 | AJ29: =SUM($AI$2:AI29) -> 5
A30: Total | H30: 10.85 | I30: 0 | J30: 0 | K30: 0 | L30: 0.29 | M30: 0 | N30: 10.85 | O30: 733.6 | P30: 60.27 | Q30: 0 | R30: =IF(A30<>"",IF(A30="Total","",A30),IF(D30<>"",R29,"")) | S30: =IF(AND(D30<>"",A30<>"Total"),1,0) -> 0 | T30: =IF(S30=1, DATE(YEAR(Settings!$B$3), MONTH(D30), DAY(D30)), "") | U30: =IF(S30=1,IFERROR(INDEX(Settings!$B$12:$B$41,MATCH($B30,Settings!$A$12:$A$41,0)),"N"),"") | V30: =IF(S30=1,IFERROR(INDEX(Settings!$C$12:$C$41,MATCH($B30,Settings!$A$12:$A$41,0)),""),"") | W30: =IF(S30=1,IFERROR(INDEX(Settings!$D$12:$D$41,MATCH($B30,Settings!$A$12:$A$41,0)),0),0) -> 0 | X30: =IF(AND(S30=1,U30="Y"),IF(V30="% of Sales",O30*W30,IF(V30="% of Tips",P30*W30,0)),0) -> 0 | Y30: =IF(S30=1,P30-X30,"") | Z30: =IF(S30=1,IFERROR(INDEX(Settings!$E$12:$E$41,MATCH($B30,Settings!$A$12:$A$41,0)),"N"),"") | AA30: =IF(S30=1,IFERROR(INDEX(Settings!$F$12:$F$41,MATCH($B30,Settings!$A$12:$A$41,0)),0),0) -> 0 | AB30: =IF(S30=1,IFERROR(INDEX(Settings!$G$12:$G$41,MATCH($B30,Settings!$A$12:$A$41,0)),0),0) -> 0 | AC30: =IF(S30=1,SUMIFS($X$2:$X$601,$S$2:$S$601,1,$T$2:$T$601,T30),"") | AD30: =IF(S30=1,SUMIFS($N$2:$N$601,$S$2:$S$601,1,$T$2:$T$601,T30,$B$2:$B$601,B30),"") | AE30: =IF(S30=1,SUMIFS($N$2:$N$601,$S$2:$S$601,1,$T$2:$T$601,T30,$Z$2:$Z$601,"Y"),"") | AF30: =IF(S30=1,SUMPRODUCT(($S$2:$S$601=1)*($T$2:$T$601=T30)*($Z$2:$Z$601="Y")*($N$2:$N$601)*($AB$2:$AB$601)),"") | AG30: =IF(AND(S30=1,Z30="Y"),IF(Settings!$B$6="Percentage",IF(AD30=0,0,AC30*AA30*(N30/AD30)),IF(Settings!$B$6="Points",IF(AF30=0,0,AC30*(N30*AB30)/AF30),IF(Settings!$B$6="Equally",IF(AE30=0,0,AC30*N30/AE30),0))),0) -> 0 | AH30: =IF(S30=1,Y30+AG30,"") | AI30: =IF(S30=1,IF(COUNTIFS($R$2:R30,R30,$S$2:S30,1)=1,1,0),0) -> 0 | AJ30: =SUM($AI$2:AI30) -> 5
R31: =IF(A31<>"",IF(A31="Total","",A31),IF(D31<>"",R30,"")) | S31: =IF(AND(D31<>"",A31<>"Total"),1,0) -> 0 | T31: =IF(S31=1, DATE(YEAR(Settings!$B$3), MONTH(D31), DAY(D31)), "") | U31: =IF(S31=1,IFERROR(INDEX(Settings!$B$12:$B$41,MATCH($B31,Settings!$A$12:$A$41,0)),"N"),"") | V31: =IF(S31=1,IFERROR(INDEX(Settings!$C$12:$C$41,MATCH($B31,Settings!$A$12:$A$41,0)),""),"") | W31: =IF(S31=1,IFERROR(INDEX(Settings!$D$12:$D$41,MATCH($B31,Settings!$A$12:$A$41,0)),0),0) -> 0 | X31: =IF(AND(S31=1,U31="Y"),IF(V31="% of Sales",O31*W31,IF(V31="% of Tips",P31*W31,0)),0) -> 0 | Y31: =IF(S31=1,P31-X31,"") | Z31: =IF(S31=1,IFERROR(INDEX(Settings!$E$12:$E$41,MATCH($B31,Settings!$A$12:$A$41,0)),"N"),"") | AA31: =IF(S31=1,IFERROR(INDEX(Settings!$F$12:$F$41,MATCH($B31,Settings!$A$12:$A$41,0)),0),0) -> 0 | AB31: =IF(S31=1,IFERROR(INDEX(Settings!$G$12:$G$41,MATCH($B31,Settings!$A$12:$A$41,0)),0),0) -> 0 | AC31: =IF(S31=1,SUMIFS($X$2:$X$601,$S$2:$S$601,1,$T$2:$T$601,T31),"") | AD31: =IF(S31=1,SUMIFS($N$2:$N$601,$S$2:$S$601,1,$T$2:$T$601,T31,$B$2:$B$601,B31),"") | AE31: =IF(S31=1,SUMIFS($N$2:$N$601,$S$2:$S$601,1,$T$2:$T$601,T31,$Z$2:$Z$601,"Y"),"") | AF31: =IF(S31=1,SUMPRODUCT(($S$2:$S$601=1)*($T$2:$T$601=T31)*($Z$2:$Z$601="Y")*($N$2:$N$601)*($AB$2:$AB$601)),"") | AG31: =IF(AND(S31=1,Z31="Y"),IF(Settings!$B$6="Percentage",IF(AD31=0,0,AC31*AA31*(N31/AD31)),IF(Settings!$B$6="Points",IF(AF31=0,0,AC31*(N31*AB31)/AF31),IF(Settings!$B$6="Equally",IF(AE31=0,0,AC31*N31/AE31),0))),0) -> 0 | AH31: =IF(S31=1,Y31+AG31,"") | AI31: =IF(S31=1,IF(COUNTIFS($R$2:R31,R31,$S$2:S31,1)=1,1,0),0) -> 0 | AJ31: =SUM($AI$2:AI31) -> 5
